<?xml version="1.0" ?>
<!-- =================================================================================== -->
<!-- |    This document was autogenerated by xacro from staubli_bhand.xacro            | -->
<!-- |    EDITING THIS FILE BY HAND IS NOT RECOMMENDED                                 | -->
<!-- =================================================================================== -->
<robot name="staubli_bhand">
    <!-- links -->
    <link name="staubli_rx60l_link1">
        <inertial>
            <mass value="0.1"/>
            <origin rpy="0 0 0" xyz="0 0 0"/>
            <inertia ixx="0.01" ixy="0" ixz="0" iyy="0.01" iyz="0" izz="0.01"/>
        </inertial>
        <visual>
            <origin rpy="0 0 0" xyz="0 0 0"/>
            <geometry>
                <mesh filename="package://staubli_description/meshes/tx60l/collada/1.dae" scale=".001 .001 .001"/>
            </geometry>
            <material name="Yellow">
                <color rgba="245 196 0 1.0"/>
            </material>
        </visual>
        <!--<collision>-->
            <!--<origin rpy="0 0 0" xyz="0 0 0"/>-->
            <!--<geometry>-->
                <!--<mesh filename="package://staubli_description/meshes/tx60l/collada/1.dae" scale=".001 .001 .001"/>-->
            <!--</geometry>-->
            <!--<material name="Yellow">-->
                <!--<color rgba="245 196 0 1.0"/>-->
            <!--</material>-->
            <!--<inertial>-->
                <!--<origin xyz="0 0 0"/>-->
                <!--<mass value="50.573"/>-->
                <!--<inertia ixx="0.0001" ixy="0.0" ixz="0.0" iyy="0.0001" iyz="0.0" izz="0.001"/>-->
            <!--</inertial>-->
        <!--</collision>-->
    </link>
    <link name="staubli_rx60l_link2">
        <inertial>
            <mass value="0.1"/>
            <origin rpy="0 0 0" xyz="0 0 0"/>
            <inertia ixx="0.01" ixy="0" ixz="0" iyy="0.01" iyz="0" izz="0.01"/>
        </inertial>
        <visual>
            <origin rpy="0 0 0" xyz="0 0 0"/>
            <geometry>
                <mesh filename="package://staubli_description/meshes/tx60l/collada/2.dae" scale=".001 .001 .001"/>
            </geometry>
            <material name="Black">
                <color rgba="0 0 0 1.0"/>
            </material>
        </visual>
        <!--<collision>-->
            <!--<origin rpy="0 0 0" xyz="0 0 0"/>-->
            <!--<geometry>-->
                <!--<mesh filename="package://staubli_description/meshes/tx60l/collada/2.dae" scale=".001 .001 .001"/>-->
            <!--</geometry>-->
            <!--<material name="Black">-->
                <!--<color rgba="0 0 0 1.0"/>-->
            <!--</material>-->
            <!--<inertial>-->
                <!--<origin xyz="0 0 0"/>-->
                <!--<mass value="50.573"/>-->
                <!--<inertia ixx="0.0001" ixy="0.0" ixz="0.0" iyy="0.0001" iyz="0.0" izz="0.001"/>-->
            <!--</inertial>-->
        <!--</collision>-->
    </link>
    <link name="staubli_rx60l_link3">
        <inertial>
            <mass value="0.1"/>
            <origin rpy="0 0 0" xyz="0 0 0"/>
            <inertia ixx="0.01" ixy="0" ixz="0" iyy="0.01" iyz="0" izz="0.01"/>
        </inertial>
        <visual>
            <origin rpy="0 0 0" xyz="-0.4 0 0"/>
            <geometry>
                <mesh filename="package://staubli_description/meshes/tx60l/collada/3.dae" scale=".001 .001 .001"/>
            </geometry>
            <material name="White">
                <color rgba="255 255 255 1.0"/>
            </material>
        </visual>
        <!--<collision>-->
            <!--<origin rpy="0 0 0" xyz="-0.4 0 0"/>-->
            <!--<geometry>-->
                <!--<mesh filename="package://staubli_description/meshes/tx60l/collada/3.dae" scale=".001 .001 .001"/>-->
            <!--</geometry>-->
            <!--<material name="White">-->
                <!--<color rgba="255 255 255 1.0"/>-->
            <!--</material>-->
        <!--</collision>-->
    </link>
    <link name="staubli_rx60l_link4">
        <inertial>
            <mass value="0.1"/>
            <origin rpy="0 0 0" xyz="0 0 0"/>
            <inertia ixx="0.01" ixy="0" ixz="0" iyy="0.01" iyz="0" izz="0.01"/>
        </inertial>
        <visual>
            <origin rpy="0 0 0" xyz="0 0 0"/>
            <geometry>
                <mesh filename="package://staubli_description/meshes/tx60l/collada/4.dae" scale=".001 .001 .001"/>
            </geometry>
            <material name="Blue"/>
        </visual>
        <!--<collision>-->
            <!--<origin rpy="0 0 0" xyz="0 0 0"/>-->
            <!--<geometry>-->
                <!--<mesh filename="package://staubli_description/meshes/tx60l/collada/4.dae" scale=".001 .001 .001"/>-->
            <!--</geometry>-->
            <!--<material name="Blue">-->
                <!--<color rgba="0 0 255 1.0"/>-->
            <!--</material>-->
        <!--</collision>-->
    </link>
    <link name="staubli_rx60l_link5">
        <inertial>
            <mass value="0.1"/>
            <origin rpy="0 0 0" xyz="0 0 0"/>
            <inertia ixx="0.01" ixy="0" ixz="0" iyy="0.01" iyz="0" izz="0.01"/>
        </inertial>
        <visual>
            <origin rpy="0 0 0" xyz="0 0 0"/>
            <geometry>
                <mesh filename="package://staubli_description/meshes/tx60l/collada/5.dae" scale=".001 .001 .001"/>
            </geometry>
            <material name="Blue"/>
        </visual>
        <!--<collision>-->
            <!--<origin rpy="0 0 0" xyz="0 0 0"/>-->
            <!--<geometry>-->
                <!--<mesh filename="package://staubli_description/meshes/tx60l/collada/5.dae" scale=".001 .001 .001"/>-->
            <!--</geometry>-->
            <!--<material name="Blue">-->
                <!--<color rgba="0 0 255 1.0"/>-->
            <!--</material>-->
        <!--</collision>-->
    </link>
    <link name="staubli_rx60l_link6">
        <inertial>
            <mass value="0.1"/>
            <origin rpy="0 0 0" xyz="0 0 0"/>
            <inertia ixx="0.01" ixy="0" ixz="0" iyy="0.01" iyz="0" izz="0.01"/>
        </inertial>
        <visual>
            <origin rpy="0 0 0" xyz="0 0 0"/>
            <geometry>
                <mesh filename="package://staubli_description/meshes/tx60l/collada/6.dae" scale=".001 .001 .001"/>
            </geometry>
            <material name="Blue"/>
        </visual>
        <!--<collision>-->
            <!--<origin rpy="0 0 0" xyz="0 0 0"/>-->
            <!--<geometry>-->
                <!--<mesh filename="package://staubli_description/meshes/tx60l/collada/6.dae" scale=".001 .001 .001"/>-->
            <!--</geometry>-->
            <!--<material name="Blue">-->
                <!--<color rgba="0 0 255 1.0"/>-->
            <!--</material>-->
        <!--</collision>-->
    </link>
    <link name="staubli_rx60l_link7">
        <inertial>
            <mass value="0.1"/>
            <origin rpy="0 0 0" xyz="0 0 0"/>
            <inertia ixx="0.01" ixy="0" ixz="0" iyy="0.01" iyz="0" izz="0.01"/>
        </inertial>
        <visual>
            <origin rpy="0 0 0" xyz="0 0 0"/>
            <geometry>
                <mesh filename="package://staubli_description/meshes/tx60l/collada/7.dae" scale=".001 .001 .001"/>
            </geometry>
            <material name="Gray">
                <color rgba="100 100 100 1.0"/>
            </material>
        </visual>
        <!--<collision>-->
            <!--<origin rpy="0 0 0" xyz="0 0 0"/>-->
            <!--<geometry>-->
                <!--<mesh filename="package://staubli_description/meshes/tx60l/collada/7.dae" scale=".001 .001 .001"/>-->
            <!--</geometry>-->
            <!--<material name="Gray">-->
                <!--<color rgba="100 100 100 1.0"/>-->
            <!--</material>-->
        <!--</collision>-->
    </link>
    <link name="staubli_rx60l_tool0">
        <inertial>
            <mass value="0.1"/>
            <origin rpy="0 0 0" xyz="0 0 0"/>
            <inertia ixx="0.01" ixy="0" ixz="0" iyy="0.01" iyz="0" izz="0.01"/>
        </inertial>
    </link>

    <!-- joints -->
    <joint name="joint_1" type="revolute">
        <origin rpy="1.57079 0.0 3.1415" xyz="0 0 0"/>
        <parent link="staubli_rx60l_link1"/>
        <child link="staubli_rx60l_link2"/>
        <axis xyz="0 1 0"/>
        <limit effort="100" lower="-2.792526803" upper="2.792526803" velocity="5.009094953"/>
    </joint>
    <joint name="joint_2" type="revolute">
        <origin rpy="0 0 -1.5707" xyz="0 0.0 0.1606"/>
        <parent link="staubli_rx60l_link2"/>
        <child link="staubli_rx60l_link3"/>
        <axis xyz="0 0 1"/>
        <limit effort="100" lower="-2.225294796" upper="2.225294796" velocity="5.009094953"/>
    </joint>
    <joint name="joint_3" type="revolute">
        <origin rpy="1.5707 0 -1.5707" xyz="-0.4 0.0 -0.1406"/>
        <parent link="staubli_rx60l_link3"/>
        <child link="staubli_rx60l_link4"/>
        <axis xyz="0 1 0"/>
        <limit effort="100" lower="-2.347467844" upper="2.347467844" velocity="5.567600314"/>
    </joint>
    <joint name="joint_4" type="revolute">
        <origin rpy="1.571 -0.000 3.142" xyz="0 0 0.45"/>
        <parent link="staubli_rx60l_link4"/>
        <child link="staubli_rx60l_link5"/>
        <axis xyz="0 1 0"/>
        <limit effort="100" lower="-4.71238898" upper="4.71238898" velocity="7.155849933"/>
    </joint>
    <joint name="joint_5" type="revolute">
        <origin rpy="1.571 0.000 3.142" xyz="0 0 0.0"/>
        <parent link="staubli_rx60l_link5"/>
        <child link="staubli_rx60l_link6"/>
        <axis xyz="0 1 0"/>
        <limit effort="100" lower="-1.78" upper="1.86" velocity="5.585053606"/>
    </joint>
    <joint name="joint_6" type="revolute">
        <origin xyz="0 0 0.07"/>
        <parent link="staubli_rx60l_link6"/>
        <child link="staubli_rx60l_link7"/>
        <axis xyz="0 0 1"/>
        <limit effort="100" lower="-6.2" upper="6.2" velocity="12.217304764"/>
    </joint>
    <joint name="joint_6-tool0" type="fixed">
        <parent link="staubli_rx60l_link7"/>
        <child link="staubli_rx60l_tool0"/>
        <origin rpy="0 0 0" xyz="0 0 0"/>
    </joint>
    <link name="wrist_load_cell">
        <visual>
            <material name="ATIGreen">
                <color rgba="0.4 1.0 0.4 1.0"/>
            </material>
            <origin rpy="0 0 0" xyz="0 0 0"/>
            <geometry>
                <cylinder length="0.0775" radius="0.05"/>
            </geometry>
        </visual>
        <collision>
            <material name="ATIGreen">
                <color rgba="0.4 1.0 0.4 1.0"/>
            </material>
            <origin rpy="0 0 0" xyz="0 0 0"/>
            <geometry>
                <cylinder length="0.0775" radius="0.065"/>
            </geometry>
        </collision>
        <inertial>
            <origin xyz="0 0 0"/>
            <mass value="0.50573"/>
            <inertia ixx="0.0001" ixy="0.0" ixz="0.0" iyy="0.0001" iyz="0.0" izz="0.001"/>
        </inertial>
    </link>
    <joint name="ati_load_cell_joint" type="fixed">
        <origin rpy="0 0 0" xyz="0 0 0.03875"/>
        <parent link="staubli_rx60l_link7"/>
        <child link="wrist_load_cell"/>
    </joint>
    <link name="barrett_mount_link">
        <visual>
            <origin rpy="0 0 0" xyz="0.0 0.02 0"/>
            <material name="ATIGreen">
                <color rgba="0.4 1.0 0.4 1.0"/>
            </material>
            <geometry>
                <box size="0.12 0.15 0.03"/>
            </geometry>
        </visual>
        <collision>
            <origin rpy="0 0 0" xyz="0.0 0.02 0"/>
            <material name="ATIGreen">
                <color rgba="0.4 1.0 0.4 1.0"/>
            </material>
            <geometry>
                <cylinder length="0.0775" radius="0.065"/>
            </geometry>
        </collision>
        <inertial>
            <origin xyz="0 0 0"/>
            <mass value="0.50573"/>
            <inertia ixx="0.0001" ixy="0.0" ixz="0.0" iyy="0.0001" iyz="0.0" izz="0.001"/>
        </inertial>
    </link>
    <joint name="barrett_mount_joint" type="fixed">
        <origin rpy="0 0 5.0614" xyz="0 0 0.0625"/>
        <parent link="staubli_rx60l_link7"/>
        <child link="barrett_mount_link"/>
    </joint>
    <link name="approach_tran">
        <inertial>
            <origin xyz="0 0 0"/>
            <mass value="0.001"/>
            <inertia ixx="0.0001" ixy="0.0" ixz="0.0" iyy="0.0001" iyz="0.0" izz="0.001"/>
        </inertial>
    </link>
    <joint name="approach_tran_joint" type="fixed">
        <origin rpy="0 0 5.0614" xyz="0 0 0.149"/>
        <parent link="staubli_rx60l_link7"/>
        <child link="approach_tran"/>
    </joint>
    <joint name="bh_base_joint" type="fixed">
        <origin rpy="0 0 5.0614" xyz="0 0 0.0705"/>
        <parent link="staubli_rx60l_link7"/>
        <child link="bh_base_link"/>
    </joint>
    <!-- HAND WORLD_LINK (RED) -->
    <link name="bh_base_link">
        <inertial>
            <mass value="1.0"/>
            <origin xyz="0 0 0"/>
            <inertia ixx="1.0" ixy="0.0" ixz="0.0" iyy="1.0" iyz="0.0" izz="1.0"/>
        </inertial>
        <visual>
            <origin rpy="0 0 0" xyz="0 0 0"/>
            <geometry>
                <mesh filename="package://barrett_hand_description/meshes/palm_280.dae"/>
            </geometry>
            <material name="White">
                <color rgba="255 255 255 0.8"/>
            </material>
        </visual>
        <collision>
            <origin rpy="0 0 0 " xyz="0 0 0"/>
            <geometry>
                <mesh filename="package://barrett_hand_description/meshes/palm_280.dae"/>
            </geometry>
            <contact_coefficients kd="1.0" kp="1000.0" mu="0"/>
        </collision>
    </link>
    <!-- finger 3 -->
    <!-- finger 32 link -->
    <link name="bh_finger_32_link">
        <inertial>
            <mass value="0.1"/>
            <origin rpy="0 0 0" xyz="0 0 0"/>
            <inertia ixx="0.01" ixy="0" ixz="0" iyy="0.01" iyz="0" izz="0.01"/>
        </inertial>
        <visual>
            <origin rpy="0 0 0" xyz="0 0 0"/>
            <geometry>
                <mesh filename="package://barrett_hand_description/meshes/finger.dae"/>
            </geometry>
            <material name="Blue"/>
        </visual>
        <collision>
            <origin rpy="0 0 0" xyz="0 0 0"/>
            <geometry>
                <mesh filename="package://barrett_hand_description/meshes/finger.dae"/>
            </geometry>
            <contact_coefficients kd="1.0" kp="1000.0" mu="0"/>
        </collision>
    </link>
    <!-- joint between BH_finger_31_link and BH_finger_32_link -->
    <joint name="bh_j32_joint" type="revolute">
        <parent link="bh_base_link"/>
        <child link="bh_finger_32_link"/>
        <origin rpy="1.5708 0 1.5708" xyz="0 -0.05 0.0754"/>
        <axis xyz="0 0 -1"/>
        <limit effort="30.0" lower="0.0" upper="2.44" velocity="2.0"/>
        <dynamics damping="1" friction="1.0"/>
    </joint>
    <transmission name="bh_j32_transmission">
        <type>transmission_interface/SimpleTransmission</type>
        <joint name="bh_j32_joint">
            <hardwareInterface>PositionJointInterface</hardwareInterface>
        </joint>
        <actuator name="bh_j32">
            <hardwareInterface>PositionJointInterface</hardwareInterface>
            <mechanicalReduction>1</mechanicalReduction>
            <motorTorqueConstant>1</motorTorqueConstant>
        </actuator>
    </transmission>
    <!-- finger 33 link -->
    <link name="bh_finger_33_link">
        <inertial>
            <mass value="0.1"/>
            <origin rpy="0 0 0" xyz="0 0 0"/>
            <inertia ixx="0.01" ixy="0" ixz="0" iyy="0.01" iyz="0" izz="0.01"/>
        </inertial>
        <visual>
            <origin rpy="0 0 0" xyz="0 0 0"/>
            <geometry>
                <mesh filename="package://barrett_hand_description/meshes/finger_tip.dae"/>
            </geometry>
            <material name="White"/>
        </visual>
        <collision>
            <origin rpy="0 0 0" xyz="0 0 0"/>
            <geometry>
                <mesh filename="package://barrett_hand_description/meshes/finger_tip.dae"/>
            </geometry>
            <contact_coefficients kd="1.0" kp="1000.0" mu="0"/>
        </collision>
    </link>
    <!-- joint between BH_finger_32_link and BH_finger_33_link -->
    <joint name="bh_j33_joint" type="revolute">
        <parent link="bh_finger_32_link"/>
        <child link="bh_finger_33_link"/>
        <origin rpy="0 0 0" xyz="-0.069936 0.003 0"/>
        <axis xyz="0 0 -1"/>
        <mimic joint="bh_j32_joint" multiplier="0.344262295082"/>
        <limit effort="30.0" lower="0.0" upper="0.84" velocity="2.0"/>
        <dynamics damping="1" friction="1.0"/>
    </joint>
    <transmission name="bh_j33_transmission">
        <type>transmission_interface/SimpleTransmission</type>
        <joint name="bh_j33_joint">
            <hardwareInterface>PositionJointInterface</hardwareInterface>
        </joint>
        <actuator name="bh_j33">
            <hardwareInterface>PositionJointInterface</hardwareInterface>
            <mechanicalReduction>1</mechanicalReduction>
            <motorTorqueConstant>1</motorTorqueConstant>
        </actuator>
    </transmission>
    <!-- finger 1 -->
    <!-- finger 11 link -->
    <link name="bh_finger_11_link">
        <inertial>
            <mass value="0.1"/>
            <origin rpy="0 0 0" xyz="-0.046 0 0"/>
            <inertia ixx="0.01" ixy="0" ixz="0" iyy="0.01" iyz="0" izz="0.01"/>
        </inertial>
        <visual>
            <origin rpy="0 0 0" xyz="0 0 0"/>
            <geometry>
                <mesh filename="package://barrett_hand_description/meshes/knuckle.dae"/>
            </geometry>
            <material name="Green"/>
        </visual>
        <collision>
            <origin rpy="0 0 0" xyz="0 0 0"/>
            <geometry>
                <mesh filename="package://barrett_hand_description/meshes/knuckle.dae"/>
            </geometry>
        </collision>
    </link>
    <!-- joint between BH_palm_link and BH_finger_11_link -->
    <joint name="bh_j11_joint" type="revolute">
        <parent link="bh_base_link"/>
        <child link="bh_finger_11_link"/>
        <origin rpy="0 0 -1.5708" xyz="0.025 0 0.0415"/>
        <axis xyz="0 0 -1"/>
        <limit effort="30.0" lower="0" upper="3.1416" velocity="2.0"/>
        <dynamics damping="1" friction="1.0"/>
    </joint>
    <transmission name="bh_j11_transmission">
        <type>transmission_interface/SimpleTransmission</type>
        <joint name="bh_j11_joint">
            <hardwareInterface>PositionJointInterface</hardwareInterface>
        </joint>
        <actuator name="bh_j11">
            <hardwareInterface>PositionJointInterface</hardwareInterface>
            <mechanicalReduction>1</mechanicalReduction>
            <motorTorqueConstant>1</motorTorqueConstant>
        </actuator>
    </transmission>
    <!-- finger 12 link -->
    <link name="bh_finger_12_link">
        <inertial>
            <mass value="0.1"/>
            <origin rpy="0 0 0" xyz="0 0 0"/>
            <inertia ixx="0.01" ixy="0" ixz="0" iyy="0.01" iyz="0" izz="0.01"/>
        </inertial>
        <visual>
            <origin rpy="0 0 0" xyz="0 0 0"/>
            <geometry>
                <mesh filename="package://barrett_hand_description/meshes/finger.dae"/>
            </geometry>
            <material name="Blue"/>
        </visual>
        <collision>
            <origin rpy="0 0 0" xyz="0 0 0"/>
            <geometry>
                <mesh filename="package://barrett_hand_description/meshes/finger.dae"/>
            </geometry>
            <contact_coefficients kd="1.0" kp="1000.0" mu="0"/>
        </collision>
    </link>
    <!-- joint between BH_finger_11_link and BH_finger_12_link -->
    <joint name="bh_j12_joint" type="revolute">
        <parent link="bh_finger_11_link"/>
        <child link="bh_finger_12_link"/>
        <origin rpy="1.5708 0 0" xyz="-0.05 0 0.0339"/>
        <axis xyz="0 0 -1"/>
        <limit effort="30.0" lower="0.0" upper="2.44" velocity="2.0"/>
        <dynamics damping="1" friction="1.0"/>
    </joint>
    <transmission name="bh_j12_transmission">
        <type>transmission_interface/SimpleTransmission</type>
        <joint name="bh_j12_joint">
            <hardwareInterface>PositionJointInterface</hardwareInterface>
        </joint>
        <actuator name="bh_j12">
            <hardwareInterface>PositionJointInterface</hardwareInterface>
            <mechanicalReduction>1</mechanicalReduction>
            <motorTorqueConstant>1</motorTorqueConstant>
        </actuator>
    </transmission>
    <!-- finger 13 link -->
    <link name="bh_finger_13_link">
        <inertial>
            <mass value="0.1"/>
            <origin rpy="0 0 0" xyz="0 0 0"/>
            <inertia ixx="0.01" ixy="0" ixz="0" iyy="0.01" iyz="0" izz="0.01"/>
        </inertial>
        <visual>
            <origin rpy="0 0 0" xyz="0 0 0"/>
            <geometry>
                <mesh filename="package://barrett_hand_description/meshes/finger_tip.dae"/>
            </geometry>
            <material name="White"/>
        </visual>
        <collision>
            <origin rpy="0 0 0" xyz="0 0 0"/>
            <geometry>
                <mesh filename="package://barrett_hand_description/meshes/finger_tip.dae"/>
            </geometry>
            <contact_coefficients kd="1.0" kp="1000.0" mu="0"/>
        </collision>
    </link>
    <!-- joint between BH_finger_12_link and BH_finger_13_link -->
    <joint name="bh_j13_joint" type="revolute">
        <parent link="bh_finger_12_link"/>
        <child link="bh_finger_13_link"/>
        <origin rpy="0 0 0" xyz="-0.069936 0.003 0"/>
        <axis xyz="0 0 -1"/>
        <mimic joint="bh_j12_joint" multiplier="0.344262295082"/>
        <limit effort="30.0" lower="0.0" upper="0.84" velocity="2.0"/>
        <dynamics damping="1" friction="1.0"/>
    </joint>
    <transmission name="bh_j13_transmission">
        <type>transmission_interface/SimpleTransmission</type>
        <joint name="bh_j13_joint">
            <hardwareInterface>PositionJointInterface</hardwareInterface>
        </joint>
        <actuator name="bh_j13">
            <hardwareInterface>PositionJointInterface</hardwareInterface>
            <mechanicalReduction>1</mechanicalReduction>
            <motorTorqueConstant>1</motorTorqueConstant>
        </actuator>
    </transmission>
    <!-- finger 2 -->
    <!-- finger 21 link -->
    <link name="bh_finger_21_link">
        <inertial>
            <mass value="0.1"/>
            <origin rpy="0 0 0" xyz="-0.046 0 0"/>
            <inertia ixx="0.01" ixy="0" ixz="0" iyy="0.01" iyz="0" izz="0.01"/>
        </inertial>
        <visual>
            <origin rpy="0 0 0" xyz="0 0 0"/>
            <geometry>
                <mesh filename="package://barrett_hand_description/meshes/knuckle.dae"/>
            </geometry>
            <material name="Green"/>
        </visual>
        <collision>
            <origin rpy="0 0 0" xyz="0 0 0"/>
            <geometry>
                <mesh filename="package://barrett_hand_description/meshes/knuckle.dae"/>
            </geometry>
        </collision>
    </link>
    <!-- joint between BH_palm_link and BH_finger_21_link -->
    <joint name="bh_j21_joint" type="revolute">
        <parent link="bh_base_link"/>
        <child link="bh_finger_21_link"/>
        <origin rpy="0 0 -1.5708" xyz="-0.025 0 0.0415"/>
        <axis xyz="0 0 1"/>
        <mimic joint="bh_j11_joint" multiplier="1"/>
        <limit effort="30.0" lower="0" upper="3.1416" velocity="2.0"/>
        <dynamics damping="1" friction="1.0"/>
    </joint>
    <transmission name="bh_j21_transmission">
        <type>transmission_interface/SimpleTransmission</type>
        <joint name="bh_j21_joint">
            <hardwareInterface>PositionJointInterface</hardwareInterface>
        </joint>
        <actuator name="bh_j21">
            <hardwareInterface>PositionJointInterface</hardwareInterface>
            <mechanicalReduction>1</mechanicalReduction>
            <motorTorqueConstant>1</motorTorqueConstant>
        </actuator>
    </transmission>
    <!-- finger 12 link -->
    <link name="bh_finger_22_link">
        <inertial>
            <mass value="0.1"/>
            <origin rpy="0 0 0" xyz="0 0 0"/>
            <inertia ixx="0.01" ixy="0" ixz="0" iyy="0.01" iyz="0" izz="0.01"/>
        </inertial>
        <visual>
            <origin rpy="0 0 0" xyz="0 0 0"/>
            <geometry>
                <mesh filename="package://barrett_hand_description/meshes/finger.dae"/>
            </geometry>
            <material name="Blue"/>
        </visual>
        <collision>
            <origin rpy="0 0 0" xyz="0 0 0"/>
            <geometry>
                <mesh filename="package://barrett_hand_description/meshes/finger.dae"/>
            </geometry>
            <contact_coefficients kd="1.0" kp="1000.0" mu="0"/>
        </collision>
    </link>
    <!-- joint between BH_finger_21_link and BH_finger_22_link -->
    <joint name="bh_j22_joint" type="revolute">
        <parent link="bh_finger_21_link"/>
        <child link="bh_finger_22_link"/>
        <origin rpy="1.5708 -8.8281E-17 0" xyz="-0.05 0 0.0339"/>
        <axis xyz="0 0 -1"/>
        <limit effort="30.0" lower="0.0" upper="2.44" velocity="2.0"/>
        <dynamics damping="1" friction="1.0"/>
    </joint>
    <transmission name="bh_j22_transmission">
        <type>transmission_interface/SimpleTransmission</type>
        <joint name="bh_j22_joint">
            <hardwareInterface>PositionJointInterface</hardwareInterface>
        </joint>
        <actuator name="bh_j22">
            <hardwareInterface>PositionJointInterface</hardwareInterface>
            <mechanicalReduction>1</mechanicalReduction>
            <motorTorqueConstant>1</motorTorqueConstant>
        </actuator>
    </transmission>
    <!-- finger 23 link -->
    <link name="bh_finger_23_link">
        <inertial>
            <mass value="0.1"/>
            <origin rpy="0 0 0" xyz="0 0 0"/>
            <inertia ixx="0.01" ixy="0" ixz="0" iyy="0.01" iyz="0" izz="0.01"/>
        </inertial>
        <visual>
            <origin rpy="0 0 0" xyz="0 0 0"/>
            <geometry>
                <mesh filename="package://barrett_hand_description/meshes/finger_tip.dae"/>
            </geometry>
            <material name="White"/>
        </visual>
        <collision>
            <origin rpy="0 0 0" xyz="0 0 0"/>
            <geometry>
                <mesh filename="package://barrett_hand_description/meshes/finger_tip.dae"/>
            </geometry>
            <contact_coefficients kd="1.0" kp="1000.0" mu="0"/>
        </collision>
    </link>
    <!-- joint between BH_finger_22_link and BH_finger_23_link -->
    <joint name="bh_j23_joint" type="revolute">
        <parent link="bh_finger_22_link"/>
        <child link="bh_finger_23_link"/>
        <origin rpy="0 0 0" xyz="-0.069936 0.003 0"/>
        <axis xyz="0 0 -1"/>
        <mimic joint="bh_j22_joint" multiplier="0.344262295082"/>
        <limit effort="30.0" lower="0.0" upper="0.84" velocity="2.0"/>
        <dynamics damping="1" friction="1.0"/>
    </joint>
    <transmission name="bh_j23_transmission">
        <type>transmission_interface/SimpleTransmission</type>
        <joint name="bh_j23_joint">
            <hardwareInterface>PositionJointInterface</hardwareInterface>
        </joint>
        <actuator name="bh_j23">
            <hardwareInterface>PositionJointInterface</hardwareInterface>
            <mechanicalReduction>1</mechanicalReduction>
            <motorTorqueConstant>1</motorTorqueConstant>
        </actuator>
    </transmission>
    <gazebo>
        <plugin filename="libgazebo_mimic_plugin.so" name="mimic_plugin">
            <joint>bh_j11_joint</joint>
            <mimicJoint>bh_j21_joint</mimicJoint>
            <multiplier>1</multiplier>
        </plugin>
    </gazebo>
    <gazebo>
        <plugin filename="libgazebo_mimic_plugin.so" name="mimic_plugin">
            <joint>bh_j12_joint</joint>
            <mimicJoint>bh_j13_joint</mimicJoint>
            <multiplier>0.344</multiplier>
        </plugin>
    </gazebo>
    <gazebo>
        <plugin filename="libgazebo_mimic_plugin.so" name="mimic_plugin">
            <joint>bh_j22_joint</joint>
            <mimicJoint>bh_j23_joint</mimicJoint>
            <multiplier>0.344</multiplier>
        </plugin>
    </gazebo>
    <gazebo>
        <plugin filename="libgazebo_mimic_plugin.so" name="mimic_plugin">
            <joint>bh_j32_joint</joint>
            <mimicJoint>bh_j33_joint</mimicJoint>
            <multiplier>0.344</multiplier>
        </plugin>
    </gazebo>
    <gazebo reference="bh_base_link">
        <material>Gazebo/White</material>
        <turnGravityOff>False</turnGravityOff>
    </gazebo>
    <gazebo reference="bh_finger_31_link">
        <material>Gazebo/Grey</material>
        <turnGravityOff>False</turnGravityOff>
    </gazebo>
    <gazebo reference="bh_finger_32_link">
        <material>Gazebo/Grey</material>
        <turnGravityOff>False</turnGravityOff>
    </gazebo>
    <gazebo reference="bh_finger_33_link">
        <material>Gazebo/Grey</material>
        <turnGravityOff>False</turnGravityOff>
    </gazebo>
    <gazebo reference="bh_finger_11_link">
        <material>Gazebo/Grey</material>
        <turnGravityOff>False</turnGravityOff>
    </gazebo>
    <gazebo reference="bh_finger_12_link">
        <material>Gazebo/Grey</material>
        <turnGravityOff>False</turnGravityOff>
    </gazebo>
    <gazebo reference="bh_finger_13_link">
        <material>Gazebo/Grey</material>
        <turnGravityOff>False</turnGravityOff>
    </gazebo>
    <gazebo reference="bh_finger_21_link">
        <material>Gazebo/Grey</material>
        <turnGravityOff>False</turnGravityOff>
    </gazebo>
    <gazebo reference="bh_finger_22_link">
        <material>Gazebo/Grey</material>
        <turnGravityOff>False</turnGravityOff>
    </gazebo>
    <gazebo reference="bh_finger_23_link">
        <material>Gazebo/Grey</material>
        <turnGravityOff>False</turnGravityOff>
    </gazebo>
    <!-- Imaginary joints for transform from tactile sensors -->
    <!-- Radian value obtained from graspit description of 40 degrees -->
    <joint name="bh_finger_14_joint" type="fixed">
        <parent link="bh_finger_13_link"/>
        <child link="bh_finger_14_link"/>
        <origin rpy="0 0 0.872665" xyz="0 0 0"/>
    </joint>
    <link name="bh_finger_14_link">
        <inertial>
            <mass value="0.1"/>
            <origin rpy="0 0 0" xyz="0 0 0"/>
            <inertia ixx="0.01" ixy="0" ixz="0" iyy="0.01" iyz="0" izz="0.01"/>
        </inertial>
    </link>
    <joint name="bh_finger_24_joint" type="fixed">
        <parent link="bh_finger_23_link"/>
        <child link="bh_finger_24_link"/>
        <origin rpy="0 0 0.872665" xyz="0 0 0"/>
    </joint>
    <link name="bh_finger_24_link">
        <inertial>
            <mass value="0.1"/>
            <origin rpy="0 0 0" xyz="0 0 0"/>
            <inertia ixx="0.01" ixy="0" ixz="0" iyy="0.01" iyz="0" izz="0.01"/>
        </inertial>
    </link>
    <joint name="bh_finger_34_joint" type="fixed">
        <parent link="bh_finger_33_link"/>
        <child link="bh_finger_34_link"/>
        <origin rpy="0 0 0.872665" xyz="0 0 0"/>
    </joint>
    <link name="bh_finger_34_link">
        <inertial>
            <mass value="0.1"/>
            <origin rpy="0 0 0" xyz="0 0 0"/>
            <inertia ixx="0.01" ixy="0" ixz="0" iyy="0.01" iyz="0" izz="0.01"/>
        </inertial>
    </link>
    <!-- Auto generated tactile sensor links -->
    <joint name="bh_palm_sensor1_joint" type="fixed">
        <origin rpy="0 0 0" xyz="-0.022 0.0165 0.075"/>
        <parent link="bh_base_link"/>
        <child link="bh_palm_sensor_1_link"/>
    </joint>
    <link name="bh_palm_sensor_1_link">
        <inertial>
            <mass value="0.1"/>
            <origin rpy="0 0 0" xyz="0 0 0"/>
            <inertia ixx="0.01" ixy="0" ixz="0" iyy="0.01" iyz="0" izz="0.01"/>
        </inertial>
        <visual>
            <origin rpy="0 0 0" xyz="0 0 0"/>
            <material name="Blue"/>
            <geometry>
                <box size="0.01 0.01 0.0095"/>
            </geometry>
        </visual>
        <collision>
            <origin rpy="0 0 0 " xyz="0 0 0"/>
            <geometry>
                <box size="0.01 0.01 0.0095"/>
            </geometry>
        </collision>
    </link>
    <joint name="bh_palm_sensor2_joint" type="fixed">
        <origin rpy="0 0 0" xyz="-0.011 0.0165 0.075"/>
        <parent link="bh_base_link"/>
        <child link="bh_palm_sensor_2_link"/>
    </joint>
    <link name="bh_palm_sensor_2_link">
        <inertial>
            <mass value="0.1"/>
            <origin rpy="0 0 0" xyz="0 0 0"/>
            <inertia ixx="0.01" ixy="0" ixz="0" iyy="0.01" iyz="0" izz="0.01"/>
        </inertial>
        <visual>
            <origin rpy="0 0 0" xyz="0 0 0"/>
            <material name="Blue"/>
            <geometry>
                <box size="0.01 0.01 0.0095"/>
            </geometry>
        </visual>
        <collision>
            <origin rpy="0 0 0 " xyz="0 0 0"/>
            <geometry>
                <box size="0.01 0.01 0.0095"/>
            </geometry>
        </collision>
    </link>
    <joint name="bh_palm_sensor3_joint" type="fixed">
        <origin rpy="0 0 0" xyz="0.0 0.0165 0.075"/>
        <parent link="bh_base_link"/>
        <child link="bh_palm_sensor_3_link"/>
    </joint>
    <link name="bh_palm_sensor_3_link">
        <inertial>
            <mass value="0.1"/>
            <origin rpy="0 0 0" xyz="0 0 0"/>
            <inertia ixx="0.01" ixy="0" ixz="0" iyy="0.01" iyz="0" izz="0.01"/>
        </inertial>
        <visual>
            <origin rpy="0 0 0" xyz="0 0 0"/>
            <material name="Blue"/>
            <geometry>
                <box size="0.01 0.01 0.0095"/>
            </geometry>
        </visual>
        <collision>
            <origin rpy="0 0 0 " xyz="0 0 0"/>
            <geometry>
                <box size="0.01 0.01 0.0095"/>
            </geometry>
        </collision>
    </link>
    <joint name="bh_palm_sensor4_joint" type="fixed">
        <origin rpy="0 0 0" xyz="0.011 0.0165 0.075"/>
        <parent link="bh_base_link"/>
        <child link="bh_palm_sensor_4_link"/>
    </joint>
    <link name="bh_palm_sensor_4_link">
        <inertial>
            <mass value="0.1"/>
            <origin rpy="0 0 0" xyz="0 0 0"/>
            <inertia ixx="0.01" ixy="0" ixz="0" iyy="0.01" iyz="0" izz="0.01"/>
        </inertial>
        <visual>
            <origin rpy="0 0 0" xyz="0 0 0"/>
            <material name="Blue"/>
            <geometry>
                <box size="0.01 0.01 0.0095"/>
            </geometry>
        </visual>
        <collision>
            <origin rpy="0 0 0 " xyz="0 0 0"/>
            <geometry>
                <box size="0.01 0.01 0.0095"/>
            </geometry>
        </collision>
    </link>
    <joint name="bh_palm_sensor5_joint" type="fixed">
        <origin rpy="0 0 0" xyz="0.022 0.0165 0.075"/>
        <parent link="bh_base_link"/>
        <child link="bh_palm_sensor_5_link"/>
    </joint>
    <link name="bh_palm_sensor_5_link">
        <inertial>
            <mass value="0.1"/>
            <origin rpy="0 0 0" xyz="0 0 0"/>
            <inertia ixx="0.01" ixy="0" ixz="0" iyy="0.01" iyz="0" izz="0.01"/>
        </inertial>
        <visual>
            <origin rpy="0 0 0" xyz="0 0 0"/>
            <material name="Blue"/>
            <geometry>
                <box size="0.01 0.01 0.0095"/>
            </geometry>
        </visual>
        <collision>
            <origin rpy="0 0 0 " xyz="0 0 0"/>
            <geometry>
                <box size="0.01 0.01 0.0095"/>
            </geometry>
        </collision>
    </link>
    <joint name="bh_palm_sensor6_joint" type="fixed">
        <origin rpy="0 0 0" xyz="-0.033 0.0055 0.075"/>
        <parent link="bh_base_link"/>
        <child link="bh_palm_sensor_6_link"/>
    </joint>
    <link name="bh_palm_sensor_6_link">
        <inertial>
            <mass value="0.1"/>
            <origin rpy="0 0 0" xyz="0 0 0"/>
            <inertia ixx="0.01" ixy="0" ixz="0" iyy="0.01" iyz="0" izz="0.01"/>
        </inertial>
        <visual>
            <origin rpy="0 0 0" xyz="0 0 0"/>
            <material name="Blue"/>
            <geometry>
                <box size="0.01 0.01 0.0095"/>
            </geometry>
        </visual>
        <collision>
            <origin rpy="0 0 0 " xyz="0 0 0"/>
            <geometry>
                <box size="0.01 0.01 0.0095"/>
            </geometry>
        </collision>
    </link>
    <joint name="bh_palm_sensor7_joint" type="fixed">
        <origin rpy="0 0 0" xyz="-0.022 0.0055 0.075"/>
        <parent link="bh_base_link"/>
        <child link="bh_palm_sensor_7_link"/>
    </joint>
    <link name="bh_palm_sensor_7_link">
        <inertial>
            <mass value="0.1"/>
            <origin rpy="0 0 0" xyz="0 0 0"/>
            <inertia ixx="0.01" ixy="0" ixz="0" iyy="0.01" iyz="0" izz="0.01"/>
        </inertial>
        <visual>
            <origin rpy="0 0 0" xyz="0 0 0"/>
            <material name="Blue"/>
            <geometry>
                <box size="0.01 0.01 0.0095"/>
            </geometry>
        </visual>
        <collision>
            <origin rpy="0 0 0 " xyz="0 0 0"/>
            <geometry>
                <box size="0.01 0.01 0.0095"/>
            </geometry>
        </collision>
    </link>
    <joint name="bh_palm_sensor8_joint" type="fixed">
        <origin rpy="0 0 0" xyz="-0.011 0.0055 0.075"/>
        <parent link="bh_base_link"/>
        <child link="bh_palm_sensor_8_link"/>
    </joint>
    <link name="bh_palm_sensor_8_link">
        <inertial>
            <mass value="0.1"/>
            <origin rpy="0 0 0" xyz="0 0 0"/>
            <inertia ixx="0.01" ixy="0" ixz="0" iyy="0.01" iyz="0" izz="0.01"/>
        </inertial>
        <visual>
            <origin rpy="0 0 0" xyz="0 0 0"/>
            <material name="Blue"/>
            <geometry>
                <box size="0.01 0.01 0.0095"/>
            </geometry>
        </visual>
        <collision>
            <origin rpy="0 0 0 " xyz="0 0 0"/>
            <geometry>
                <box size="0.01 0.01 0.0095"/>
            </geometry>
        </collision>
    </link>
    <joint name="bh_palm_sensor9_joint" type="fixed">
        <origin rpy="0 0 0" xyz="0.0 0.0055 0.075"/>
        <parent link="bh_base_link"/>
        <child link="bh_palm_sensor_9_link"/>
    </joint>
    <link name="bh_palm_sensor_9_link">
        <inertial>
            <mass value="0.1"/>
            <origin rpy="0 0 0" xyz="0 0 0"/>
            <inertia ixx="0.01" ixy="0" ixz="0" iyy="0.01" iyz="0" izz="0.01"/>
        </inertial>
        <visual>
            <origin rpy="0 0 0" xyz="0 0 0"/>
            <material name="Blue"/>
            <geometry>
                <box size="0.01 0.01 0.0095"/>
            </geometry>
        </visual>
        <collision>
            <origin rpy="0 0 0 " xyz="0 0 0"/>
            <geometry>
                <box size="0.01 0.01 0.0095"/>
            </geometry>
        </collision>
    </link>
    <joint name="bh_palm_sensor10_joint" type="fixed">
        <origin rpy="0 0 0" xyz="0.011 0.0055 0.075"/>
        <parent link="bh_base_link"/>
        <child link="bh_palm_sensor_10_link"/>
    </joint>
    <link name="bh_palm_sensor_10_link">
        <inertial>
            <mass value="0.1"/>
            <origin rpy="0 0 0" xyz="0 0 0"/>
            <inertia ixx="0.01" ixy="0" ixz="0" iyy="0.01" iyz="0" izz="0.01"/>
        </inertial>
        <visual>
            <origin rpy="0 0 0" xyz="0 0 0"/>
            <material name="Blue"/>
            <geometry>
                <box size="0.01 0.01 0.0095"/>
            </geometry>
        </visual>
        <collision>
            <origin rpy="0 0 0 " xyz="0 0 0"/>
            <geometry>
                <box size="0.01 0.01 0.0095"/>
            </geometry>
        </collision>
    </link>
    <joint name="bh_palm_sensor11_joint" type="fixed">
        <origin rpy="0 0 0" xyz="0.022 0.0055 0.075"/>
        <parent link="bh_base_link"/>
        <child link="bh_palm_sensor_11_link"/>
    </joint>
    <link name="bh_palm_sensor_11_link">
        <inertial>
            <mass value="0.1"/>
            <origin rpy="0 0 0" xyz="0 0 0"/>
            <inertia ixx="0.01" ixy="0" ixz="0" iyy="0.01" iyz="0" izz="0.01"/>
        </inertial>
        <visual>
            <origin rpy="0 0 0" xyz="0 0 0"/>
            <material name="Blue"/>
            <geometry>
                <box size="0.01 0.01 0.0095"/>
            </geometry>
        </visual>
        <collision>
            <origin rpy="0 0 0 " xyz="0 0 0"/>
            <geometry>
                <box size="0.01 0.01 0.0095"/>
            </geometry>
        </collision>
    </link>
    <joint name="bh_palm_sensor12_joint" type="fixed">
        <origin rpy="0 0 0" xyz="0.033 0.0055 0.075"/>
        <parent link="bh_base_link"/>
        <child link="bh_palm_sensor_12_link"/>
    </joint>
    <link name="bh_palm_sensor_12_link">
        <inertial>
            <mass value="0.1"/>
            <origin rpy="0 0 0" xyz="0 0 0"/>
            <inertia ixx="0.01" ixy="0" ixz="0" iyy="0.01" iyz="0" izz="0.01"/>
        </inertial>
        <visual>
            <origin rpy="0 0 0" xyz="0 0 0"/>
            <material name="Blue"/>
            <geometry>
                <box size="0.01 0.01 0.0095"/>
            </geometry>
        </visual>
        <collision>
            <origin rpy="0 0 0 " xyz="0 0 0"/>
            <geometry>
                <box size="0.01 0.01 0.0095"/>
            </geometry>
        </collision>
    </link>
    <joint name="bh_palm_sensor13_joint" type="fixed">
        <origin rpy="0 0 0" xyz="-0.033 -0.0055 0.075"/>
        <parent link="bh_base_link"/>
        <child link="bh_palm_sensor_13_link"/>
    </joint>
    <link name="bh_palm_sensor_13_link">
        <inertial>
            <mass value="0.1"/>
            <origin rpy="0 0 0" xyz="0 0 0"/>
            <inertia ixx="0.01" ixy="0" ixz="0" iyy="0.01" iyz="0" izz="0.01"/>
        </inertial>
        <visual>
            <origin rpy="0 0 0" xyz="0 0 0"/>
            <material name="Blue"/>
            <geometry>
                <box size="0.01 0.01 0.0095"/>
            </geometry>
        </visual>
        <collision>
            <origin rpy="0 0 0 " xyz="0 0 0"/>
            <geometry>
                <box size="0.01 0.01 0.0095"/>
            </geometry>
        </collision>
    </link>
    <joint name="bh_palm_sensor14_joint" type="fixed">
        <origin rpy="0 0 0" xyz="-0.022 -0.0055 0.075"/>
        <parent link="bh_base_link"/>
        <child link="bh_palm_sensor_14_link"/>
    </joint>
    <link name="bh_palm_sensor_14_link">
        <inertial>
            <mass value="0.1"/>
            <origin rpy="0 0 0" xyz="0 0 0"/>
            <inertia ixx="0.01" ixy="0" ixz="0" iyy="0.01" iyz="0" izz="0.01"/>
        </inertial>
        <visual>
            <origin rpy="0 0 0" xyz="0 0 0"/>
            <material name="Blue"/>
            <geometry>
                <box size="0.01 0.01 0.0095"/>
            </geometry>
        </visual>
        <collision>
            <origin rpy="0 0 0 " xyz="0 0 0"/>
            <geometry>
                <box size="0.01 0.01 0.0095"/>
            </geometry>
        </collision>
    </link>
    <joint name="bh_palm_sensor15_joint" type="fixed">
        <origin rpy="0 0 0" xyz="-0.011 -0.0055 0.075"/>
        <parent link="bh_base_link"/>
        <child link="bh_palm_sensor_15_link"/>
    </joint>
    <link name="bh_palm_sensor_15_link">
        <inertial>
            <mass value="0.1"/>
            <origin rpy="0 0 0" xyz="0 0 0"/>
            <inertia ixx="0.01" ixy="0" ixz="0" iyy="0.01" iyz="0" izz="0.01"/>
        </inertial>
        <visual>
            <origin rpy="0 0 0" xyz="0 0 0"/>
            <material name="Blue"/>
            <geometry>
                <box size="0.01 0.01 0.0095"/>
            </geometry>
        </visual>
        <collision>
            <origin rpy="0 0 0 " xyz="0 0 0"/>
            <geometry>
                <box size="0.01 0.01 0.0095"/>
            </geometry>
        </collision>
    </link>
    <joint name="bh_palm_sensor16_joint" type="fixed">
        <origin rpy="0 0 0" xyz="0.0 -0.0055 0.075"/>
        <parent link="bh_base_link"/>
        <child link="bh_palm_sensor_16_link"/>
    </joint>
    <link name="bh_palm_sensor_16_link">
        <inertial>
            <mass value="0.1"/>
            <origin rpy="0 0 0" xyz="0 0 0"/>
            <inertia ixx="0.01" ixy="0" ixz="0" iyy="0.01" iyz="0" izz="0.01"/>
        </inertial>
        <visual>
            <origin rpy="0 0 0" xyz="0 0 0"/>
            <material name="Blue"/>
            <geometry>
                <box size="0.01 0.01 0.0095"/>
            </geometry>
        </visual>
        <collision>
            <origin rpy="0 0 0 " xyz="0 0 0"/>
            <geometry>
                <box size="0.01 0.01 0.0095"/>
            </geometry>
        </collision>
    </link>
    <joint name="bh_palm_sensor17_joint" type="fixed">
        <origin rpy="0 0 0" xyz="0.011 -0.0055 0.075"/>
        <parent link="bh_base_link"/>
        <child link="bh_palm_sensor_17_link"/>
    </joint>
    <link name="bh_palm_sensor_17_link">
        <inertial>
            <mass value="0.1"/>
            <origin rpy="0 0 0" xyz="0 0 0"/>
            <inertia ixx="0.01" ixy="0" ixz="0" iyy="0.01" iyz="0" izz="0.01"/>
        </inertial>
        <visual>
            <origin rpy="0 0 0" xyz="0 0 0"/>
            <material name="Blue"/>
            <geometry>
                <box size="0.01 0.01 0.0095"/>
            </geometry>
        </visual>
        <collision>
            <origin rpy="0 0 0 " xyz="0 0 0"/>
            <geometry>
                <box size="0.01 0.01 0.0095"/>
            </geometry>
        </collision>
    </link>
    <joint name="bh_palm_sensor18_joint" type="fixed">
        <origin rpy="0 0 0" xyz="0.022 -0.0055 0.075"/>
        <parent link="bh_base_link"/>
        <child link="bh_palm_sensor_18_link"/>
    </joint>
    <link name="bh_palm_sensor_18_link">
        <inertial>
            <mass value="0.1"/>
            <origin rpy="0 0 0" xyz="0 0 0"/>
            <inertia ixx="0.01" ixy="0" ixz="0" iyy="0.01" iyz="0" izz="0.01"/>
        </inertial>
        <visual>
            <origin rpy="0 0 0" xyz="0 0 0"/>
            <material name="Blue"/>
            <geometry>
                <box size="0.01 0.01 0.0095"/>
            </geometry>
        </visual>
        <collision>
            <origin rpy="0 0 0 " xyz="0 0 0"/>
            <geometry>
                <box size="0.01 0.01 0.0095"/>
            </geometry>
        </collision>
    </link>
    <joint name="bh_palm_sensor19_joint" type="fixed">
        <origin rpy="0 0 0" xyz="0.033 -0.0055 0.075"/>
        <parent link="bh_base_link"/>
        <child link="bh_palm_sensor_19_link"/>
    </joint>
    <link name="bh_palm_sensor_19_link">
        <inertial>
            <mass value="0.1"/>
            <origin rpy="0 0 0" xyz="0 0 0"/>
            <inertia ixx="0.01" ixy="0" ixz="0" iyy="0.01" iyz="0" izz="0.01"/>
        </inertial>
        <visual>
            <origin rpy="0 0 0" xyz="0 0 0"/>
            <material name="Blue"/>
            <geometry>
                <box size="0.01 0.01 0.0095"/>
            </geometry>
        </visual>
        <collision>
            <origin rpy="0 0 0 " xyz="0 0 0"/>
            <geometry>
                <box size="0.01 0.01 0.0095"/>
            </geometry>
        </collision>
    </link>
    <joint name="bh_palm_sensor20_joint" type="fixed">
        <origin rpy="0 0 0" xyz="-0.022 -0.0165 0.075"/>
        <parent link="bh_base_link"/>
        <child link="bh_palm_sensor_20_link"/>
    </joint>
    <link name="bh_palm_sensor_20_link">
        <inertial>
            <mass value="0.1"/>
            <origin rpy="0 0 0" xyz="0 0 0"/>
            <inertia ixx="0.01" ixy="0" ixz="0" iyy="0.01" iyz="0" izz="0.01"/>
        </inertial>
        <visual>
            <origin rpy="0 0 0" xyz="0 0 0"/>
            <material name="Blue"/>
            <geometry>
                <box size="0.01 0.01 0.0095"/>
            </geometry>
        </visual>
        <collision>
            <origin rpy="0 0 0 " xyz="0 0 0"/>
            <geometry>
                <box size="0.01 0.01 0.0095"/>
            </geometry>
        </collision>
    </link>
    <joint name="bh_palm_sensor21_joint" type="fixed">
        <origin rpy="0 0 0" xyz="-0.011 -0.0165 0.075"/>
        <parent link="bh_base_link"/>
        <child link="bh_palm_sensor_21_link"/>
    </joint>
    <link name="bh_palm_sensor_21_link">
        <inertial>
            <mass value="0.1"/>
            <origin rpy="0 0 0" xyz="0 0 0"/>
            <inertia ixx="0.01" ixy="0" ixz="0" iyy="0.01" iyz="0" izz="0.01"/>
        </inertial>
        <visual>
            <origin rpy="0 0 0" xyz="0 0 0"/>
            <material name="Blue"/>
            <geometry>
                <box size="0.01 0.01 0.0095"/>
            </geometry>
        </visual>
        <collision>
            <origin rpy="0 0 0 " xyz="0 0 0"/>
            <geometry>
                <box size="0.01 0.01 0.0095"/>
            </geometry>
        </collision>
    </link>
    <joint name="bh_palm_sensor22_joint" type="fixed">
        <origin rpy="0 0 0" xyz="0.0 -0.0165 0.075"/>
        <parent link="bh_base_link"/>
        <child link="bh_palm_sensor_22_link"/>
    </joint>
    <link name="bh_palm_sensor_22_link">
        <inertial>
            <mass value="0.1"/>
            <origin rpy="0 0 0" xyz="0 0 0"/>
            <inertia ixx="0.01" ixy="0" ixz="0" iyy="0.01" iyz="0" izz="0.01"/>
        </inertial>
        <visual>
            <origin rpy="0 0 0" xyz="0 0 0"/>
            <material name="Blue"/>
            <geometry>
                <box size="0.01 0.01 0.0095"/>
            </geometry>
        </visual>
        <collision>
            <origin rpy="0 0 0 " xyz="0 0 0"/>
            <geometry>
                <box size="0.01 0.01 0.0095"/>
            </geometry>
        </collision>
    </link>
    <joint name="bh_palm_sensor23_joint" type="fixed">
        <origin rpy="0 0 0" xyz="0.011 -0.0165 0.075"/>
        <parent link="bh_base_link"/>
        <child link="bh_palm_sensor_23_link"/>
    </joint>
    <link name="bh_palm_sensor_23_link">
        <inertial>
            <mass value="0.1"/>
            <origin rpy="0 0 0" xyz="0 0 0"/>
            <inertia ixx="0.01" ixy="0" ixz="0" iyy="0.01" iyz="0" izz="0.01"/>
        </inertial>
        <visual>
            <origin rpy="0 0 0" xyz="0 0 0"/>
            <material name="Blue"/>
            <geometry>
                <box size="0.01 0.01 0.0095"/>
            </geometry>
        </visual>
        <collision>
            <origin rpy="0 0 0 " xyz="0 0 0"/>
            <geometry>
                <box size="0.01 0.01 0.0095"/>
            </geometry>
        </collision>
    </link>
    <joint name="bh_palm_sensor24_joint" type="fixed">
        <origin rpy="0 0 0" xyz="0.022 -0.0165 0.075"/>
        <parent link="bh_base_link"/>
        <child link="bh_palm_sensor_24_link"/>
    </joint>
    <link name="bh_palm_sensor_24_link">
        <inertial>
            <mass value="0.1"/>
            <origin rpy="0 0 0" xyz="0 0 0"/>
            <inertia ixx="0.01" ixy="0" ixz="0" iyy="0.01" iyz="0" izz="0.01"/>
        </inertial>
        <visual>
            <origin rpy="0 0 0" xyz="0 0 0"/>
            <material name="Blue"/>
            <geometry>
                <box size="0.01 0.01 0.0095"/>
            </geometry>
        </visual>
        <collision>
            <origin rpy="0 0 0 " xyz="0 0 0"/>
            <geometry>
                <box size="0.01 0.01 0.0095"/>
            </geometry>
        </collision>
    </link>
    <joint name="bh_link1_sensor1_joint" type="fixed">
        <origin rpy="0 0 0" xyz="0.0105 0.02225 -0.005175"/>
        <parent link="bh_finger_14_link"/>
        <child link="bh_link1_sensor1_link"/>
    </joint>
    <link name="bh_link1_sensor1_link">
        <inertial>
            <mass value="0.1"/>
            <origin rpy="0 0 0" xyz="0 0 0"/>
            <inertia ixx="0.01" ixy="0" ixz="0" iyy="0.01" iyz="0" izz="0.01"/>
        </inertial>
        <visual>
            <origin rpy="0 0 0" xyz="0 0 0"/>
            <material name="Blue"/>
            <geometry>
                <box size="0.0015 0.0055 0.00465"/>
            </geometry>
        </visual>
        <collision>
            <origin rpy="0 0 0" xyz="0 0 0"/>
            <material name="Blue"/>
            <geometry>
                <box size="0.0015 0.0055 0.00465"/>
            </geometry>
        </collision>
    </link>
    <joint name="bh_link1_sensor2_joint" type="fixed">
        <origin rpy="0 0 0" xyz="0.0105 0.02225 0.0"/>
        <parent link="bh_finger_14_link"/>
        <child link="bh_link1_sensor2_link"/>
    </joint>
    <link name="bh_link1_sensor2_link">
        <inertial>
            <mass value="0.1"/>
            <origin rpy="0 0 0" xyz="0 0 0"/>
            <inertia ixx="0.01" ixy="0" ixz="0" iyy="0.01" iyz="0" izz="0.01"/>
        </inertial>
        <visual>
            <origin rpy="0 0 0" xyz="0 0 0"/>
            <material name="Blue"/>
            <geometry>
                <box size="0.0015 0.0055 0.0047"/>
            </geometry>
        </visual>
        <collision>
            <origin rpy="0 0 0" xyz="0 0 0"/>
            <material name="Blue"/>
            <geometry>
                <box size="0.0015 0.0055 0.0047"/>
            </geometry>
        </collision>
    </link>
    <joint name="bh_link1_sensor3_joint" type="fixed">
        <origin rpy="0 0 0" xyz="0.0105 0.02225 0.0052"/>
        <parent link="bh_finger_14_link"/>
        <child link="bh_link1_sensor3_link"/>
    </joint>
    <link name="bh_link1_sensor3_link">
        <inertial>
            <mass value="0.1"/>
            <origin rpy="0 0 0" xyz="0 0 0"/>
            <inertia ixx="0.01" ixy="0" ixz="0" iyy="0.01" iyz="0" izz="0.01"/>
        </inertial>
        <visual>
            <origin rpy="0 0 0" xyz="0 0 0"/>
            <material name="Blue"/>
            <geometry>
                <box size="0.0015 0.0055 0.0047"/>
            </geometry>
        </visual>
        <collision>
            <origin rpy="0 0 0" xyz="0 0 0"/>
            <material name="Blue"/>
            <geometry>
                <box size="0.0015 0.0055 0.0047"/>
            </geometry>
        </collision>
    </link>
    <joint name="bh_link1_sensor4_joint" type="fixed">
        <origin rpy="0 0 0" xyz="0.0105 0.02825 -0.005175"/>
        <parent link="bh_finger_14_link"/>
        <child link="bh_link1_sensor4_link"/>
    </joint>
    <link name="bh_link1_sensor4_link">
        <inertial>
            <mass value="0.1"/>
            <origin rpy="0 0 0" xyz="0 0 0"/>
            <inertia ixx="0.01" ixy="0" ixz="0" iyy="0.01" iyz="0" izz="0.01"/>
        </inertial>
        <visual>
            <origin rpy="0 0 0" xyz="0 0 0"/>
            <material name="Blue"/>
            <geometry>
                <box size="0.0015 0.0055 0.00465"/>
            </geometry>
        </visual>
        <collision>
            <origin rpy="0 0 0" xyz="0 0 0"/>
            <material name="Blue"/>
            <geometry>
                <box size="0.0015 0.0055 0.00465"/>
            </geometry>
        </collision>
    </link>
    <joint name="bh_link1_sensor5_joint" type="fixed">
        <origin rpy="0 0 0" xyz="0.0105 0.02825 0.0"/>
        <parent link="bh_finger_14_link"/>
        <child link="bh_link1_sensor5_link"/>
    </joint>
    <link name="bh_link1_sensor5_link">
        <inertial>
            <mass value="0.1"/>
            <origin rpy="0 0 0" xyz="0 0 0"/>
            <inertia ixx="0.01" ixy="0" ixz="0" iyy="0.01" iyz="0" izz="0.01"/>
        </inertial>
        <visual>
            <origin rpy="0 0 0" xyz="0 0 0"/>
            <material name="Blue"/>
            <geometry>
                <box size="0.0015 0.0055 0.0047"/>
            </geometry>
        </visual>
        <collision>
            <origin rpy="0 0 0" xyz="0 0 0"/>
            <material name="Blue"/>
            <geometry>
                <box size="0.0015 0.0055 0.0047"/>
            </geometry>
        </collision>
    </link>
    <joint name="bh_link1_sensor6_joint" type="fixed">
        <origin rpy="0 0 0" xyz="0.0105 0.02825 0.0052"/>
        <parent link="bh_finger_14_link"/>
        <child link="bh_link1_sensor6_link"/>
    </joint>
    <link name="bh_link1_sensor6_link">
        <inertial>
            <mass value="0.1"/>
            <origin rpy="0 0 0" xyz="0 0 0"/>
            <inertia ixx="0.01" ixy="0" ixz="0" iyy="0.01" iyz="0" izz="0.01"/>
        </inertial>
        <visual>
            <origin rpy="0 0 0" xyz="0 0 0"/>
            <material name="Blue"/>
            <geometry>
                <box size="0.0015 0.0055 0.0047"/>
            </geometry>
        </visual>
        <collision>
            <origin rpy="0 0 0" xyz="0 0 0"/>
            <material name="Blue"/>
            <geometry>
                <box size="0.0015 0.0055 0.0047"/>
            </geometry>
        </collision>
    </link>
    <joint name="bh_link1_sensor7_joint" type="fixed">
        <origin rpy="0 0 0" xyz="0.0105 0.03425 -0.005175"/>
        <parent link="bh_finger_14_link"/>
        <child link="bh_link1_sensor7_link"/>
    </joint>
    <link name="bh_link1_sensor7_link">
        <inertial>
            <mass value="0.1"/>
            <origin rpy="0 0 0" xyz="0 0 0"/>
            <inertia ixx="0.01" ixy="0" ixz="0" iyy="0.01" iyz="0" izz="0.01"/>
        </inertial>
        <visual>
            <origin rpy="0 0 0" xyz="0 0 0"/>
            <material name="Blue"/>
            <geometry>
                <box size="0.0015 0.0055 0.00465"/>
            </geometry>
        </visual>
        <collision>
            <origin rpy="0 0 0" xyz="0 0 0"/>
            <material name="Blue"/>
            <geometry>
                <box size="0.0015 0.0055 0.00465"/>
            </geometry>
        </collision>
    </link>
    <joint name="bh_link1_sensor8_joint" type="fixed">
        <origin rpy="0 0 0" xyz="0.0105 0.03425 0.0"/>
        <parent link="bh_finger_14_link"/>
        <child link="bh_link1_sensor8_link"/>
    </joint>
    <link name="bh_link1_sensor8_link">
        <inertial>
            <mass value="0.1"/>
            <origin rpy="0 0 0" xyz="0 0 0"/>
            <inertia ixx="0.01" ixy="0" ixz="0" iyy="0.01" iyz="0" izz="0.01"/>
        </inertial>
        <visual>
            <origin rpy="0 0 0" xyz="0 0 0"/>
            <material name="Blue"/>
            <geometry>
                <box size="0.0015 0.0055 0.0047"/>
            </geometry>
        </visual>
        <collision>
            <origin rpy="0 0 0" xyz="0 0 0"/>
            <material name="Blue"/>
            <geometry>
                <box size="0.0015 0.0055 0.0047"/>
            </geometry>
        </collision>
    </link>
    <joint name="bh_link1_sensor9_joint" type="fixed">
        <origin rpy="0 0 0" xyz="0.0105 0.03425 0.0052"/>
        <parent link="bh_finger_14_link"/>
        <child link="bh_link1_sensor9_link"/>
    </joint>
    <link name="bh_link1_sensor9_link">
        <inertial>
            <mass value="0.1"/>
            <origin rpy="0 0 0" xyz="0 0 0"/>
            <inertia ixx="0.01" ixy="0" ixz="0" iyy="0.01" iyz="0" izz="0.01"/>
        </inertial>
        <visual>
            <origin rpy="0 0 0" xyz="0 0 0"/>
            <material name="Blue"/>
            <geometry>
                <box size="0.0015 0.0055 0.0047"/>
            </geometry>
        </visual>
        <collision>
            <origin rpy="0 0 0" xyz="0 0 0"/>
            <material name="Blue"/>
            <geometry>
                <box size="0.0015 0.0055 0.0047"/>
            </geometry>
        </collision>
    </link>
    <joint name="bh_link1_sensor10_joint" type="fixed">
        <origin rpy="0 0 0" xyz="0.0105 0.04025 -0.005175"/>
        <parent link="bh_finger_14_link"/>
        <child link="bh_link1_sensor10_link"/>
    </joint>
    <link name="bh_link1_sensor10_link">
        <inertial>
            <mass value="0.1"/>
            <origin rpy="0 0 0" xyz="0 0 0"/>
            <inertia ixx="0.01" ixy="0" ixz="0" iyy="0.01" iyz="0" izz="0.01"/>
        </inertial>
        <visual>
            <origin rpy="0 0 0" xyz="0 0 0"/>
            <material name="Blue"/>
            <geometry>
                <box size="0.0015 0.0055 0.00465"/>
            </geometry>
        </visual>
        <collision>
            <origin rpy="0 0 0" xyz="0 0 0"/>
            <material name="Blue"/>
            <geometry>
                <box size="0.0015 0.0055 0.00465"/>
            </geometry>
        </collision>
    </link>
    <joint name="bh_link1_sensor11_joint" type="fixed">
        <origin rpy="0 0 0" xyz="0.0105 0.04025 0.0"/>
        <parent link="bh_finger_14_link"/>
        <child link="bh_link1_sensor11_link"/>
    </joint>
    <link name="bh_link1_sensor11_link">
        <inertial>
            <mass value="0.1"/>
            <origin rpy="0 0 0" xyz="0 0 0"/>
            <inertia ixx="0.01" ixy="0" ixz="0" iyy="0.01" iyz="0" izz="0.01"/>
        </inertial>
        <visual>
            <origin rpy="0 0 0" xyz="0 0 0"/>
            <material name="Blue"/>
            <geometry>
                <box size="0.0015 0.0055 0.0047"/>
            </geometry>
        </visual>
        <collision>
            <origin rpy="0 0 0" xyz="0 0 0"/>
            <material name="Blue"/>
            <geometry>
                <box size="0.0015 0.0055 0.0047"/>
            </geometry>
        </collision>
    </link>
    <joint name="bh_link1_sensor12_joint" type="fixed">
        <origin rpy="0 0 0" xyz="0.0105 0.04025 0.0052"/>
        <parent link="bh_finger_14_link"/>
        <child link="bh_link1_sensor12_link"/>
    </joint>
    <link name="bh_link1_sensor12_link">
        <inertial>
            <mass value="0.1"/>
            <origin rpy="0 0 0" xyz="0 0 0"/>
            <inertia ixx="0.01" ixy="0" ixz="0" iyy="0.01" iyz="0" izz="0.01"/>
        </inertial>
        <visual>
            <origin rpy="0 0 0" xyz="0 0 0"/>
            <material name="Blue"/>
            <geometry>
                <box size="0.0015 0.0055 0.0047"/>
            </geometry>
        </visual>
        <collision>
            <origin rpy="0 0 0" xyz="0 0 0"/>
            <material name="Blue"/>
            <geometry>
                <box size="0.0015 0.0055 0.0047"/>
            </geometry>
        </collision>
    </link>
    <joint name="bh_link1_sensor13_joint" type="fixed">
        <origin rpy="0 0 0" xyz="0.0095 0.04625 -0.005175"/>
        <parent link="bh_finger_14_link"/>
        <child link="bh_link1_sensor13_link"/>
    </joint>
    <link name="bh_link1_sensor13_link">
        <inertial>
            <mass value="0.1"/>
            <origin rpy="0 0 0" xyz="0 0 0"/>
            <inertia ixx="0.01" ixy="0" ixz="0" iyy="0.01" iyz="0" izz="0.01"/>
        </inertial>
        <visual>
            <origin rpy="0 0 0" xyz="0 0 0"/>
            <material name="Blue"/>
            <geometry>
                <box size="0.0015 0.0055 0.00465"/>
            </geometry>
        </visual>
        <collision>
            <origin rpy="0 0 0" xyz="0 0 0"/>
            <material name="Blue"/>
            <geometry>
                <box size="0.0015 0.0055 0.00465"/>
            </geometry>
        </collision>
    </link>
    <joint name="bh_link1_sensor14_joint" type="fixed">
        <origin rpy="0 0 0" xyz="0.0095 0.04625 0.0"/>
        <parent link="bh_finger_14_link"/>
        <child link="bh_link1_sensor14_link"/>
    </joint>
    <link name="bh_link1_sensor14_link">
        <inertial>
            <mass value="0.1"/>
            <origin rpy="0 0 0" xyz="0 0 0"/>
            <inertia ixx="0.01" ixy="0" ixz="0" iyy="0.01" iyz="0" izz="0.01"/>
        </inertial>
        <visual>
            <origin rpy="0 0 0" xyz="0 0 0"/>
            <material name="Blue"/>
            <geometry>
                <box size="0.0015 0.0055 0.0047"/>
            </geometry>
        </visual>
        <collision>
            <origin rpy="0 0 0" xyz="0 0 0"/>
            <material name="Blue"/>
            <geometry>
                <box size="0.0015 0.0055 0.0047"/>
            </geometry>
        </collision>
    </link>
    <joint name="bh_link1_sensor15_joint" type="fixed">
        <origin rpy="0 0 0" xyz="0.0095 0.04625 0.0052"/>
        <parent link="bh_finger_14_link"/>
        <child link="bh_link1_sensor15_link"/>
    </joint>
    <link name="bh_link1_sensor15_link">
        <inertial>
            <mass value="0.1"/>
            <origin rpy="0 0 0" xyz="0 0 0"/>
            <inertia ixx="0.01" ixy="0" ixz="0" iyy="0.01" iyz="0" izz="0.01"/>
        </inertial>
        <visual>
            <origin rpy="0 0 0" xyz="0 0 0"/>
            <material name="Blue"/>
            <geometry>
                <box size="0.0015 0.0055 0.0047"/>
            </geometry>
        </visual>
        <collision>
            <origin rpy="0 0 0" xyz="0 0 0"/>
            <material name="Blue"/>
            <geometry>
                <box size="0.0015 0.0055 0.0047"/>
            </geometry>
        </collision>
    </link>
    <joint name="bh_link1_sensor16_joint" type="fixed">
        <origin rpy="0 0 0" xyz="0.008 0.051 -0.005175"/>
        <parent link="bh_finger_14_link"/>
        <child link="bh_link1_sensor16_link"/>
    </joint>
    <link name="bh_link1_sensor16_link">
        <inertial>
            <mass value="0.1"/>
            <origin rpy="0 0 0" xyz="0 0 0"/>
            <inertia ixx="0.01" ixy="0" ixz="0" iyy="0.01" iyz="0" izz="0.01"/>
        </inertial>
        <visual>
            <origin rpy="0 0 0" xyz="0 0 0"/>
            <material name="Blue"/>
            <geometry>
                <box size="0.003 0.003 0.00465"/>
            </geometry>
        </visual>
        <collision>
            <origin rpy="0 0 0" xyz="0 0 0"/>
            <material name="Blue"/>
            <geometry>
                <box size="0.003 0.003 0.00465"/>
            </geometry>
        </collision>
    </link>
    <joint name="bh_link1_sensor17_joint" type="fixed">
        <origin rpy="0 0 0" xyz="0.008 0.051 0.0"/>
        <parent link="bh_finger_14_link"/>
        <child link="bh_link1_sensor17_link"/>
    </joint>
    <link name="bh_link1_sensor17_link">
        <inertial>
            <mass value="0.1"/>
            <origin rpy="0 0 0" xyz="0 0 0"/>
            <inertia ixx="0.01" ixy="0" ixz="0" iyy="0.01" iyz="0" izz="0.01"/>
        </inertial>
        <visual>
            <origin rpy="0 0 0" xyz="0 0 0"/>
            <material name="Blue"/>
            <geometry>
                <box size="0.003 0.003 0.0047"/>
            </geometry>
        </visual>
        <collision>
            <origin rpy="0 0 0" xyz="0 0 0"/>
            <material name="Blue"/>
            <geometry>
                <box size="0.003 0.003 0.0047"/>
            </geometry>
        </collision>
    </link>
    <joint name="bh_link1_sensor18_joint" type="fixed">
        <origin rpy="0 0 0" xyz="0.008 0.051 0.0052"/>
        <parent link="bh_finger_14_link"/>
        <child link="bh_link1_sensor18_link"/>
    </joint>
    <link name="bh_link1_sensor18_link">
        <inertial>
            <mass value="0.1"/>
            <origin rpy="0 0 0" xyz="0 0 0"/>
            <inertia ixx="0.01" ixy="0" ixz="0" iyy="0.01" iyz="0" izz="0.01"/>
        </inertial>
        <visual>
            <origin rpy="0 0 0" xyz="0 0 0"/>
            <material name="Blue"/>
            <geometry>
                <box size="0.003 0.003 0.0047"/>
            </geometry>
        </visual>
        <collision>
            <origin rpy="0 0 0" xyz="0 0 0"/>
            <material name="Blue"/>
            <geometry>
                <box size="0.003 0.003 0.0047"/>
            </geometry>
        </collision>
    </link>
    <joint name="bh_link1_sensor19_joint" type="fixed">
        <origin rpy="0 0 0" xyz="0.005 0.05425 -0.005175"/>
        <parent link="bh_finger_14_link"/>
        <child link="bh_link1_sensor19_link"/>
    </joint>
    <link name="bh_link1_sensor19_link">
        <inertial>
            <mass value="0.1"/>
            <origin rpy="0 0 0" xyz="0 0 0"/>
            <inertia ixx="0.01" ixy="0" ixz="0" iyy="0.01" iyz="0" izz="0.01"/>
        </inertial>
        <visual>
            <origin rpy="0 0 0" xyz="0 0 0"/>
            <material name="Blue"/>
            <geometry>
                <box size="0.0065 0.0035 0.00465"/>
            </geometry>
        </visual>
        <collision>
            <origin rpy="0 0 0" xyz="0 0 0"/>
            <material name="Blue"/>
            <geometry>
                <box size="0.0065 0.0035 0.00465"/>
            </geometry>
        </collision>
    </link>
    <joint name="bh_link1_sensor20_joint" type="fixed">
        <origin rpy="0 0 0" xyz="0.005 0.05425 0.0"/>
        <parent link="bh_finger_14_link"/>
        <child link="bh_link1_sensor20_link"/>
    </joint>
    <link name="bh_link1_sensor20_link">
        <inertial>
            <mass value="0.1"/>
            <origin rpy="0 0 0" xyz="0 0 0"/>
            <inertia ixx="0.01" ixy="0" ixz="0" iyy="0.01" iyz="0" izz="0.01"/>
        </inertial>
        <visual>
            <origin rpy="0 0 0" xyz="0 0 0"/>
            <material name="Blue"/>
            <geometry>
                <box size="0.0065 0.0035 0.0047"/>
            </geometry>
        </visual>
        <collision>
            <origin rpy="0 0 0" xyz="0 0 0"/>
            <material name="Blue"/>
            <geometry>
                <box size="0.0065 0.0035 0.0047"/>
            </geometry>
        </collision>
    </link>
    <joint name="bh_link1_sensor21_joint" type="fixed">
        <origin rpy="0 0 0" xyz="0.005 0.05425 0.0052"/>
        <parent link="bh_finger_14_link"/>
        <child link="bh_link1_sensor21_link"/>
    </joint>
    <link name="bh_link1_sensor21_link">
        <inertial>
            <mass value="0.1"/>
            <origin rpy="0 0 0" xyz="0 0 0"/>
            <inertia ixx="0.01" ixy="0" ixz="0" iyy="0.01" iyz="0" izz="0.01"/>
        </inertial>
        <visual>
            <origin rpy="0 0 0" xyz="0 0 0"/>
            <material name="Blue"/>
            <geometry>
                <box size="0.0065 0.0035 0.0047"/>
            </geometry>
        </visual>
        <collision>
            <origin rpy="0 0 0" xyz="0 0 0"/>
            <material name="Blue"/>
            <geometry>
                <box size="0.0065 0.0035 0.0047"/>
            </geometry>
        </collision>
    </link>
    <joint name="bh_link1_sensor22_joint" type="fixed">
        <origin rpy="0 0 0" xyz="0.003 0.056625 -0.005175"/>
        <parent link="bh_finger_14_link"/>
        <child link="bh_link1_sensor22_link"/>
    </joint>
    <link name="bh_link1_sensor22_link">
        <inertial>
            <mass value="0.1"/>
            <origin rpy="0 0 0" xyz="0 0 0"/>
            <inertia ixx="0.01" ixy="0" ixz="0" iyy="0.01" iyz="0" izz="0.01"/>
        </inertial>
        <visual>
            <origin rpy="0 0 0" xyz="0 0 0"/>
            <material name="Blue"/>
            <geometry>
                <box size="0.00875 0.0015 0.00465"/>
            </geometry>
        </visual>
        <collision>
            <origin rpy="0 0 0" xyz="0 0 0"/>
            <material name="Blue"/>
            <geometry>
                <box size="0.00875 0.0015 0.00465"/>
            </geometry>
        </collision>
    </link>
    <joint name="bh_link1_sensor23_joint" type="fixed">
        <origin rpy="0 0 0" xyz="0.003 0.056625 0.0"/>
        <parent link="bh_finger_14_link"/>
        <child link="bh_link1_sensor23_link"/>
    </joint>
    <link name="bh_link1_sensor23_link">
        <inertial>
            <mass value="0.1"/>
            <origin rpy="0 0 0" xyz="0 0 0"/>
            <inertia ixx="0.01" ixy="0" ixz="0" iyy="0.01" iyz="0" izz="0.01"/>
        </inertial>
        <visual>
            <origin rpy="0 0 0" xyz="0 0 0"/>
            <material name="Blue"/>
            <geometry>
                <box size="0.00875 0.0015 0.0047"/>
            </geometry>
        </visual>
        <collision>
            <origin rpy="0 0 0" xyz="0 0 0"/>
            <material name="Blue"/>
            <geometry>
                <box size="0.00875 0.0015 0.0047"/>
            </geometry>
        </collision>
    </link>
    <joint name="bh_link1_sensor24_joint" type="fixed">
        <origin rpy="0 0 0" xyz="0.003 0.056625 0.0052"/>
        <parent link="bh_finger_14_link"/>
        <child link="bh_link1_sensor24_link"/>
    </joint>
    <link name="bh_link1_sensor24_link">
        <inertial>
            <mass value="0.1"/>
            <origin rpy="0 0 0" xyz="0 0 0"/>
            <inertia ixx="0.01" ixy="0" ixz="0" iyy="0.01" iyz="0" izz="0.01"/>
        </inertial>
        <visual>
            <origin rpy="0 0 0" xyz="0 0 0"/>
            <material name="Blue"/>
            <geometry>
                <box size="0.00875 0.0015 0.0047"/>
            </geometry>
        </visual>
        <collision>
            <origin rpy="0 0 0" xyz="0 0 0"/>
            <material name="Blue"/>
            <geometry>
                <box size="0.00875 0.0015 0.0047"/>
            </geometry>
        </collision>
    </link>
    <joint name="bh_link2_sensor1_joint" type="fixed">
        <origin rpy="0 0 0" xyz="0.0105 0.02225 -0.005175"/>
        <parent link="bh_finger_24_link"/>
        <child link="bh_link2_sensor1_link"/>
    </joint>
    <link name="bh_link2_sensor1_link">
        <inertial>
            <mass value="0.1"/>
            <origin rpy="0 0 0" xyz="0 0 0"/>
            <inertia ixx="0.01" ixy="0" ixz="0" iyy="0.01" iyz="0" izz="0.01"/>
        </inertial>
        <visual>
            <origin rpy="0 0 0" xyz="0 0 0"/>
            <material name="Blue"/>
            <geometry>
                <box size="0.0015 0.0055 0.00465"/>
            </geometry>
        </visual>
        <collision>
            <origin rpy="0 0 0" xyz="0 0 0"/>
            <material name="Blue"/>
            <geometry>
                <box size="0.0015 0.0055 0.00465"/>
            </geometry>
        </collision>
    </link>
    <joint name="bh_link2_sensor2_joint" type="fixed">
        <origin rpy="0 0 0" xyz="0.0105 0.02225 0.0"/>
        <parent link="bh_finger_24_link"/>
        <child link="bh_link2_sensor2_link"/>
    </joint>
    <link name="bh_link2_sensor2_link">
        <inertial>
            <mass value="0.1"/>
            <origin rpy="0 0 0" xyz="0 0 0"/>
            <inertia ixx="0.01" ixy="0" ixz="0" iyy="0.01" iyz="0" izz="0.01"/>
        </inertial>
        <visual>
            <origin rpy="0 0 0" xyz="0 0 0"/>
            <material name="Blue"/>
            <geometry>
                <box size="0.0015 0.0055 0.0047"/>
            </geometry>
        </visual>
        <collision>
            <origin rpy="0 0 0" xyz="0 0 0"/>
            <material name="Blue"/>
            <geometry>
                <box size="0.0015 0.0055 0.0047"/>
            </geometry>
        </collision>
    </link>
    <joint name="bh_link2_sensor3_joint" type="fixed">
        <origin rpy="0 0 0" xyz="0.0105 0.02225 0.0052"/>
        <parent link="bh_finger_24_link"/>
        <child link="bh_link2_sensor3_link"/>
    </joint>
    <link name="bh_link2_sensor3_link">
        <inertial>
            <mass value="0.1"/>
            <origin rpy="0 0 0" xyz="0 0 0"/>
            <inertia ixx="0.01" ixy="0" ixz="0" iyy="0.01" iyz="0" izz="0.01"/>
        </inertial>
        <visual>
            <origin rpy="0 0 0" xyz="0 0 0"/>
            <material name="Blue"/>
            <geometry>
                <box size="0.0015 0.0055 0.0047"/>
            </geometry>
        </visual>
        <collision>
            <origin rpy="0 0 0" xyz="0 0 0"/>
            <material name="Blue"/>
            <geometry>
                <box size="0.0015 0.0055 0.0047"/>
            </geometry>
        </collision>
    </link>
    <joint name="bh_link2_sensor4_joint" type="fixed">
        <origin rpy="0 0 0" xyz="0.0105 0.02825 -0.005175"/>
        <parent link="bh_finger_24_link"/>
        <child link="bh_link2_sensor4_link"/>
    </joint>
    <link name="bh_link2_sensor4_link">
        <inertial>
            <mass value="0.1"/>
            <origin rpy="0 0 0" xyz="0 0 0"/>
            <inertia ixx="0.01" ixy="0" ixz="0" iyy="0.01" iyz="0" izz="0.01"/>
        </inertial>
        <visual>
            <origin rpy="0 0 0" xyz="0 0 0"/>
            <material name="Blue"/>
            <geometry>
                <box size="0.0015 0.0055 0.00465"/>
            </geometry>
        </visual>
        <collision>
            <origin rpy="0 0 0" xyz="0 0 0"/>
            <material name="Blue"/>
            <geometry>
                <box size="0.0015 0.0055 0.00465"/>
            </geometry>
        </collision>
    </link>
    <joint name="bh_link2_sensor5_joint" type="fixed">
        <origin rpy="0 0 0" xyz="0.0105 0.02825 0.0"/>
        <parent link="bh_finger_24_link"/>
        <child link="bh_link2_sensor5_link"/>
    </joint>
    <link name="bh_link2_sensor5_link">
        <inertial>
            <mass value="0.1"/>
            <origin rpy="0 0 0" xyz="0 0 0"/>
            <inertia ixx="0.01" ixy="0" ixz="0" iyy="0.01" iyz="0" izz="0.01"/>
        </inertial>
        <visual>
            <origin rpy="0 0 0" xyz="0 0 0"/>
            <material name="Blue"/>
            <geometry>
                <box size="0.0015 0.0055 0.0047"/>
            </geometry>
        </visual>
        <collision>
            <origin rpy="0 0 0" xyz="0 0 0"/>
            <material name="Blue"/>
            <geometry>
                <box size="0.0015 0.0055 0.0047"/>
            </geometry>
        </collision>
    </link>
    <joint name="bh_link2_sensor6_joint" type="fixed">
        <origin rpy="0 0 0" xyz="0.0105 0.02825 0.0052"/>
        <parent link="bh_finger_24_link"/>
        <child link="bh_link2_sensor6_link"/>
    </joint>
    <link name="bh_link2_sensor6_link">
        <inertial>
            <mass value="0.1"/>
            <origin rpy="0 0 0" xyz="0 0 0"/>
            <inertia ixx="0.01" ixy="0" ixz="0" iyy="0.01" iyz="0" izz="0.01"/>
        </inertial>
        <visual>
            <origin rpy="0 0 0" xyz="0 0 0"/>
            <material name="Blue"/>
            <geometry>
                <box size="0.0015 0.0055 0.0047"/>
            </geometry>
        </visual>
        <collision>
            <origin rpy="0 0 0" xyz="0 0 0"/>
            <material name="Blue"/>
            <geometry>
                <box size="0.0015 0.0055 0.0047"/>
            </geometry>
        </collision>
    </link>
    <joint name="bh_link2_sensor7_joint" type="fixed">
        <origin rpy="0 0 0" xyz="0.0105 0.03425 -0.005175"/>
        <parent link="bh_finger_24_link"/>
        <child link="bh_link2_sensor7_link"/>
    </joint>
    <link name="bh_link2_sensor7_link">
        <inertial>
            <mass value="0.1"/>
            <origin rpy="0 0 0" xyz="0 0 0"/>
            <inertia ixx="0.01" ixy="0" ixz="0" iyy="0.01" iyz="0" izz="0.01"/>
        </inertial>
        <visual>
            <origin rpy="0 0 0" xyz="0 0 0"/>
            <material name="Blue"/>
            <geometry>
                <box size="0.0015 0.0055 0.00465"/>
            </geometry>
        </visual>
        <collision>
            <origin rpy="0 0 0" xyz="0 0 0"/>
            <material name="Blue"/>
            <geometry>
                <box size="0.0015 0.0055 0.00465"/>
            </geometry>
        </collision>
    </link>
    <joint name="bh_link2_sensor8_joint" type="fixed">
        <origin rpy="0 0 0" xyz="0.0105 0.03425 0.0"/>
        <parent link="bh_finger_24_link"/>
        <child link="bh_link2_sensor8_link"/>
    </joint>
    <link name="bh_link2_sensor8_link">
        <inertial>
            <mass value="0.1"/>
            <origin rpy="0 0 0" xyz="0 0 0"/>
            <inertia ixx="0.01" ixy="0" ixz="0" iyy="0.01" iyz="0" izz="0.01"/>
        </inertial>
        <visual>
            <origin rpy="0 0 0" xyz="0 0 0"/>
            <material name="Blue"/>
            <geometry>
                <box size="0.0015 0.0055 0.0047"/>
            </geometry>
        </visual>
        <collision>
            <origin rpy="0 0 0" xyz="0 0 0"/>
            <material name="Blue"/>
            <geometry>
                <box size="0.0015 0.0055 0.0047"/>
            </geometry>
        </collision>
    </link>
    <joint name="bh_link2_sensor9_joint" type="fixed">
        <origin rpy="0 0 0" xyz="0.0105 0.03425 0.0052"/>
        <parent link="bh_finger_24_link"/>
        <child link="bh_link2_sensor9_link"/>
    </joint>
    <link name="bh_link2_sensor9_link">
        <inertial>
            <mass value="0.1"/>
            <origin rpy="0 0 0" xyz="0 0 0"/>
            <inertia ixx="0.01" ixy="0" ixz="0" iyy="0.01" iyz="0" izz="0.01"/>
        </inertial>
        <visual>
            <origin rpy="0 0 0" xyz="0 0 0"/>
            <material name="Blue"/>
            <geometry>
                <box size="0.0015 0.0055 0.0047"/>
            </geometry>
        </visual>
        <collision>
            <origin rpy="0 0 0" xyz="0 0 0"/>
            <material name="Blue"/>
            <geometry>
                <box size="0.0015 0.0055 0.0047"/>
            </geometry>
        </collision>
    </link>
    <joint name="bh_link2_sensor10_joint" type="fixed">
        <origin rpy="0 0 0" xyz="0.0105 0.04025 -0.005175"/>
        <parent link="bh_finger_24_link"/>
        <child link="bh_link2_sensor10_link"/>
    </joint>
    <link name="bh_link2_sensor10_link">
        <inertial>
            <mass value="0.1"/>
            <origin rpy="0 0 0" xyz="0 0 0"/>
            <inertia ixx="0.01" ixy="0" ixz="0" iyy="0.01" iyz="0" izz="0.01"/>
        </inertial>
        <visual>
            <origin rpy="0 0 0" xyz="0 0 0"/>
            <material name="Blue"/>
            <geometry>
                <box size="0.0015 0.0055 0.00465"/>
            </geometry>
        </visual>
        <collision>
            <origin rpy="0 0 0" xyz="0 0 0"/>
            <material name="Blue"/>
            <geometry>
                <box size="0.0015 0.0055 0.00465"/>
            </geometry>
        </collision>
    </link>
    <joint name="bh_link2_sensor11_joint" type="fixed">
        <origin rpy="0 0 0" xyz="0.0105 0.04025 0.0"/>
        <parent link="bh_finger_24_link"/>
        <child link="bh_link2_sensor11_link"/>
    </joint>
    <link name="bh_link2_sensor11_link">
        <inertial>
            <mass value="0.1"/>
            <origin rpy="0 0 0" xyz="0 0 0"/>
            <inertia ixx="0.01" ixy="0" ixz="0" iyy="0.01" iyz="0" izz="0.01"/>
        </inertial>
        <visual>
            <origin rpy="0 0 0" xyz="0 0 0"/>
            <material name="Blue"/>
            <geometry>
                <box size="0.0015 0.0055 0.0047"/>
            </geometry>
        </visual>
        <collision>
            <origin rpy="0 0 0" xyz="0 0 0"/>
            <material name="Blue"/>
            <geometry>
                <box size="0.0015 0.0055 0.0047"/>
            </geometry>
        </collision>
    </link>
    <joint name="bh_link2_sensor12_joint" type="fixed">
        <origin rpy="0 0 0" xyz="0.0105 0.04025 0.0052"/>
        <parent link="bh_finger_24_link"/>
        <child link="bh_link2_sensor12_link"/>
    </joint>
    <link name="bh_link2_sensor12_link">
        <inertial>
            <mass value="0.1"/>
            <origin rpy="0 0 0" xyz="0 0 0"/>
            <inertia ixx="0.01" ixy="0" ixz="0" iyy="0.01" iyz="0" izz="0.01"/>
        </inertial>
        <visual>
            <origin rpy="0 0 0" xyz="0 0 0"/>
            <material name="Blue"/>
            <geometry>
                <box size="0.0015 0.0055 0.0047"/>
            </geometry>
        </visual>
        <collision>
            <origin rpy="0 0 0" xyz="0 0 0"/>
            <material name="Blue"/>
            <geometry>
                <box size="0.0015 0.0055 0.0047"/>
            </geometry>
        </collision>
    </link>
    <joint name="bh_link2_sensor13_joint" type="fixed">
        <origin rpy="0 0 0" xyz="0.0095 0.04625 -0.005175"/>
        <parent link="bh_finger_24_link"/>
        <child link="bh_link2_sensor13_link"/>
    </joint>
    <link name="bh_link2_sensor13_link">
        <inertial>
            <mass value="0.1"/>
            <origin rpy="0 0 0" xyz="0 0 0"/>
            <inertia ixx="0.01" ixy="0" ixz="0" iyy="0.01" iyz="0" izz="0.01"/>
        </inertial>
        <visual>
            <origin rpy="0 0 0" xyz="0 0 0"/>
            <material name="Blue"/>
            <geometry>
                <box size="0.0015 0.0055 0.00465"/>
            </geometry>
        </visual>
        <collision>
            <origin rpy="0 0 0" xyz="0 0 0"/>
            <material name="Blue"/>
            <geometry>
                <box size="0.0015 0.0055 0.00465"/>
            </geometry>
        </collision>
    </link>
    <joint name="bh_link2_sensor14_joint" type="fixed">
        <origin rpy="0 0 0" xyz="0.0095 0.04625 0.0"/>
        <parent link="bh_finger_24_link"/>
        <child link="bh_link2_sensor14_link"/>
    </joint>
    <link name="bh_link2_sensor14_link">
        <inertial>
            <mass value="0.1"/>
            <origin rpy="0 0 0" xyz="0 0 0"/>
            <inertia ixx="0.01" ixy="0" ixz="0" iyy="0.01" iyz="0" izz="0.01"/>
        </inertial>
        <visual>
            <origin rpy="0 0 0" xyz="0 0 0"/>
            <material name="Blue"/>
            <geometry>
                <box size="0.0015 0.0055 0.0047"/>
            </geometry>
        </visual>
        <collision>
            <origin rpy="0 0 0" xyz="0 0 0"/>
            <material name="Blue"/>
            <geometry>
                <box size="0.0015 0.0055 0.0047"/>
            </geometry>
        </collision>
    </link>
    <joint name="bh_link2_sensor15_joint" type="fixed">
        <origin rpy="0 0 0" xyz="0.0095 0.04625 0.0052"/>
        <parent link="bh_finger_24_link"/>
        <child link="bh_link2_sensor15_link"/>
    </joint>
    <link name="bh_link2_sensor15_link">
        <inertial>
            <mass value="0.1"/>
            <origin rpy="0 0 0" xyz="0 0 0"/>
            <inertia ixx="0.01" ixy="0" ixz="0" iyy="0.01" iyz="0" izz="0.01"/>
        </inertial>
        <visual>
            <origin rpy="0 0 0" xyz="0 0 0"/>
            <material name="Blue"/>
            <geometry>
                <box size="0.0015 0.0055 0.0047"/>
            </geometry>
        </visual>
        <collision>
            <origin rpy="0 0 0" xyz="0 0 0"/>
            <material name="Blue"/>
            <geometry>
                <box size="0.0015 0.0055 0.0047"/>
            </geometry>
        </collision>
    </link>
    <joint name="bh_link2_sensor16_joint" type="fixed">
        <origin rpy="0 0 0" xyz="0.008 0.051 -0.005175"/>
        <parent link="bh_finger_24_link"/>
        <child link="bh_link2_sensor16_link"/>
    </joint>
    <link name="bh_link2_sensor16_link">
        <inertial>
            <mass value="0.1"/>
            <origin rpy="0 0 0" xyz="0 0 0"/>
            <inertia ixx="0.01" ixy="0" ixz="0" iyy="0.01" iyz="0" izz="0.01"/>
        </inertial>
        <visual>
            <origin rpy="0 0 0" xyz="0 0 0"/>
            <material name="Blue"/>
            <geometry>
                <box size="0.003 0.003 0.00465"/>
            </geometry>
        </visual>
        <collision>
            <origin rpy="0 0 0" xyz="0 0 0"/>
            <material name="Blue"/>
            <geometry>
                <box size="0.003 0.003 0.00465"/>
            </geometry>
        </collision>
    </link>
    <joint name="bh_link2_sensor17_joint" type="fixed">
        <origin rpy="0 0 0" xyz="0.008 0.051 0.0"/>
        <parent link="bh_finger_24_link"/>
        <child link="bh_link2_sensor17_link"/>
    </joint>
    <link name="bh_link2_sensor17_link">
        <inertial>
            <mass value="0.1"/>
            <origin rpy="0 0 0" xyz="0 0 0"/>
            <inertia ixx="0.01" ixy="0" ixz="0" iyy="0.01" iyz="0" izz="0.01"/>
        </inertial>
        <visual>
            <origin rpy="0 0 0" xyz="0 0 0"/>
            <material name="Blue"/>
            <geometry>
                <box size="0.003 0.003 0.0047"/>
            </geometry>
        </visual>
        <collision>
            <origin rpy="0 0 0" xyz="0 0 0"/>
            <material name="Blue"/>
            <geometry>
                <box size="0.003 0.003 0.0047"/>
            </geometry>
        </collision>
    </link>
    <joint name="bh_link2_sensor18_joint" type="fixed">
        <origin rpy="0 0 0" xyz="0.008 0.051 0.0052"/>
        <parent link="bh_finger_24_link"/>
        <child link="bh_link2_sensor18_link"/>
    </joint>
    <link name="bh_link2_sensor18_link">
        <inertial>
            <mass value="0.1"/>
            <origin rpy="0 0 0" xyz="0 0 0"/>
            <inertia ixx="0.01" ixy="0" ixz="0" iyy="0.01" iyz="0" izz="0.01"/>
        </inertial>
        <visual>
            <origin rpy="0 0 0" xyz="0 0 0"/>
            <material name="Blue"/>
            <geometry>
                <box size="0.003 0.003 0.0047"/>
            </geometry>
        </visual>
        <collision>
            <origin rpy="0 0 0" xyz="0 0 0"/>
            <material name="Blue"/>
            <geometry>
                <box size="0.003 0.003 0.0047"/>
            </geometry>
        </collision>
    </link>
    <joint name="bh_link2_sensor19_joint" type="fixed">
        <origin rpy="0 0 0" xyz="0.005 0.05425 -0.005175"/>
        <parent link="bh_finger_24_link"/>
        <child link="bh_link2_sensor19_link"/>
    </joint>
    <link name="bh_link2_sensor19_link">
        <inertial>
            <mass value="0.1"/>
            <origin rpy="0 0 0" xyz="0 0 0"/>
            <inertia ixx="0.01" ixy="0" ixz="0" iyy="0.01" iyz="0" izz="0.01"/>
        </inertial>
        <visual>
            <origin rpy="0 0 0" xyz="0 0 0"/>
            <material name="Blue"/>
            <geometry>
                <box size="0.0065 0.0035 0.00465"/>
            </geometry>
        </visual>
        <collision>
            <origin rpy="0 0 0" xyz="0 0 0"/>
            <material name="Blue"/>
            <geometry>
                <box size="0.0065 0.0035 0.00465"/>
            </geometry>
        </collision>
    </link>
    <joint name="bh_link2_sensor20_joint" type="fixed">
        <origin rpy="0 0 0" xyz="0.005 0.05425 0.0"/>
        <parent link="bh_finger_24_link"/>
        <child link="bh_link2_sensor20_link"/>
    </joint>
    <link name="bh_link2_sensor20_link">
        <inertial>
            <mass value="0.1"/>
            <origin rpy="0 0 0" xyz="0 0 0"/>
            <inertia ixx="0.01" ixy="0" ixz="0" iyy="0.01" iyz="0" izz="0.01"/>
        </inertial>
        <visual>
            <origin rpy="0 0 0" xyz="0 0 0"/>
            <material name="Blue"/>
            <geometry>
                <box size="0.0065 0.0035 0.0047"/>
            </geometry>
        </visual>
        <collision>
            <origin rpy="0 0 0" xyz="0 0 0"/>
            <material name="Blue"/>
            <geometry>
                <box size="0.0065 0.0035 0.0047"/>
            </geometry>
        </collision>
    </link>
    <joint name="bh_link2_sensor21_joint" type="fixed">
        <origin rpy="0 0 0" xyz="0.005 0.05425 0.0052"/>
        <parent link="bh_finger_24_link"/>
        <child link="bh_link2_sensor21_link"/>
    </joint>
    <link name="bh_link2_sensor21_link">
        <inertial>
            <mass value="0.1"/>
            <origin rpy="0 0 0" xyz="0 0 0"/>
            <inertia ixx="0.01" ixy="0" ixz="0" iyy="0.01" iyz="0" izz="0.01"/>
        </inertial>
        <visual>
            <origin rpy="0 0 0" xyz="0 0 0"/>
            <material name="Blue"/>
            <geometry>
                <box size="0.0065 0.0035 0.0047"/>
            </geometry>
        </visual>
        <collision>
            <origin rpy="0 0 0" xyz="0 0 0"/>
            <material name="Blue"/>
            <geometry>
                <box size="0.0065 0.0035 0.0047"/>
            </geometry>
        </collision>
    </link>
    <joint name="bh_link2_sensor22_joint" type="fixed">
        <origin rpy="0 0 0" xyz="0.003 0.056625 -0.005175"/>
        <parent link="bh_finger_24_link"/>
        <child link="bh_link2_sensor22_link"/>
    </joint>
    <link name="bh_link2_sensor22_link">
        <inertial>
            <mass value="0.1"/>
            <origin rpy="0 0 0" xyz="0 0 0"/>
            <inertia ixx="0.01" ixy="0" ixz="0" iyy="0.01" iyz="0" izz="0.01"/>
        </inertial>
        <visual>
            <origin rpy="0 0 0" xyz="0 0 0"/>
            <material name="Blue"/>
            <geometry>
                <box size="0.00875 0.0015 0.00465"/>
            </geometry>
        </visual>
        <collision>
            <origin rpy="0 0 0" xyz="0 0 0"/>
            <material name="Blue"/>
            <geometry>
                <box size="0.00875 0.0015 0.00465"/>
            </geometry>
        </collision>
    </link>
    <joint name="bh_link2_sensor23_joint" type="fixed">
        <origin rpy="0 0 0" xyz="0.003 0.056625 0.0"/>
        <parent link="bh_finger_24_link"/>
        <child link="bh_link2_sensor23_link"/>
    </joint>
    <link name="bh_link2_sensor23_link">
        <inertial>
            <mass value="0.1"/>
            <origin rpy="0 0 0" xyz="0 0 0"/>
            <inertia ixx="0.01" ixy="0" ixz="0" iyy="0.01" iyz="0" izz="0.01"/>
        </inertial>
        <visual>
            <origin rpy="0 0 0" xyz="0 0 0"/>
            <material name="Blue"/>
            <geometry>
                <box size="0.00875 0.0015 0.0047"/>
            </geometry>
        </visual>
        <collision>
            <origin rpy="0 0 0" xyz="0 0 0"/>
            <material name="Blue"/>
            <geometry>
                <box size="0.00875 0.0015 0.0047"/>
            </geometry>
        </collision>
    </link>
    <joint name="bh_link2_sensor24_joint" type="fixed">
        <origin rpy="0 0 0" xyz="0.003 0.056625 0.0052"/>
        <parent link="bh_finger_24_link"/>
        <child link="bh_link2_sensor24_link"/>
    </joint>
    <link name="bh_link2_sensor24_link">
        <inertial>
            <mass value="0.1"/>
            <origin rpy="0 0 0" xyz="0 0 0"/>
            <inertia ixx="0.01" ixy="0" ixz="0" iyy="0.01" iyz="0" izz="0.01"/>
        </inertial>
        <visual>
            <origin rpy="0 0 0" xyz="0 0 0"/>
            <material name="Blue"/>
            <geometry>
                <box size="0.00875 0.0015 0.0047"/>
            </geometry>
        </visual>
        <collision>
            <origin rpy="0 0 0" xyz="0 0 0"/>
            <material name="Blue"/>
            <geometry>
                <box size="0.00875 0.0015 0.0047"/>
            </geometry>
        </collision>
    </link>
    <joint name="bh_link3_sensor1_joint" type="fixed">
        <origin rpy="0 0 0" xyz="0.0105 0.02225 -0.005175"/>
        <parent link="bh_finger_34_link"/>
        <child link="bh_link3_sensor1_link"/>
    </joint>
    <link name="bh_link3_sensor1_link">
        <inertial>
            <mass value="0.1"/>
            <origin rpy="0 0 0" xyz="0 0 0"/>
            <inertia ixx="0.01" ixy="0" ixz="0" iyy="0.01" iyz="0" izz="0.01"/>
        </inertial>
        <visual>
            <origin rpy="0 0 0" xyz="0 0 0"/>
            <material name="Blue"/>
            <geometry>
                <box size="0.0015 0.0055 0.00465"/>
            </geometry>
        </visual>
        <collision>
            <origin rpy="0 0 0" xyz="0 0 0"/>
            <material name="Blue"/>
            <geometry>
                <box size="0.0015 0.0055 0.00465"/>
            </geometry>
        </collision>
    </link>
    <joint name="bh_link3_sensor2_joint" type="fixed">
        <origin rpy="0 0 0" xyz="0.0105 0.02225 0.0"/>
        <parent link="bh_finger_34_link"/>
        <child link="bh_link3_sensor2_link"/>
    </joint>
    <link name="bh_link3_sensor2_link">
        <inertial>
            <mass value="0.1"/>
            <origin rpy="0 0 0" xyz="0 0 0"/>
            <inertia ixx="0.01" ixy="0" ixz="0" iyy="0.01" iyz="0" izz="0.01"/>
        </inertial>
        <visual>
            <origin rpy="0 0 0" xyz="0 0 0"/>
            <material name="Blue"/>
            <geometry>
                <box size="0.0015 0.0055 0.0047"/>
            </geometry>
        </visual>
        <collision>
            <origin rpy="0 0 0" xyz="0 0 0"/>
            <material name="Blue"/>
            <geometry>
                <box size="0.0015 0.0055 0.0047"/>
            </geometry>
        </collision>
    </link>
    <joint name="bh_link3_sensor3_joint" type="fixed">
        <origin rpy="0 0 0" xyz="0.0105 0.02225 0.0052"/>
        <parent link="bh_finger_34_link"/>
        <child link="bh_link3_sensor3_link"/>
    </joint>
    <link name="bh_link3_sensor3_link">
        <inertial>
            <mass value="0.1"/>
            <origin rpy="0 0 0" xyz="0 0 0"/>
            <inertia ixx="0.01" ixy="0" ixz="0" iyy="0.01" iyz="0" izz="0.01"/>
        </inertial>
        <visual>
            <origin rpy="0 0 0" xyz="0 0 0"/>
            <material name="Blue"/>
            <geometry>
                <box size="0.0015 0.0055 0.0047"/>
            </geometry>
        </visual>
        <collision>
            <origin rpy="0 0 0" xyz="0 0 0"/>
            <material name="Blue"/>
            <geometry>
                <box size="0.0015 0.0055 0.0047"/>
            </geometry>
        </collision>
    </link>
    <joint name="bh_link3_sensor4_joint" type="fixed">
        <origin rpy="0 0 0" xyz="0.0105 0.02825 -0.005175"/>
        <parent link="bh_finger_34_link"/>
        <child link="bh_link3_sensor4_link"/>
    </joint>
    <link name="bh_link3_sensor4_link">
        <inertial>
            <mass value="0.1"/>
            <origin rpy="0 0 0" xyz="0 0 0"/>
            <inertia ixx="0.01" ixy="0" ixz="0" iyy="0.01" iyz="0" izz="0.01"/>
        </inertial>
        <visual>
            <origin rpy="0 0 0" xyz="0 0 0"/>
            <material name="Blue"/>
            <geometry>
                <box size="0.0015 0.0055 0.00465"/>
            </geometry>
        </visual>
        <collision>
            <origin rpy="0 0 0" xyz="0 0 0"/>
            <material name="Blue"/>
            <geometry>
                <box size="0.0015 0.0055 0.00465"/>
            </geometry>
        </collision>
    </link>
    <joint name="bh_link3_sensor5_joint" type="fixed">
        <origin rpy="0 0 0" xyz="0.0105 0.02825 0.0"/>
        <parent link="bh_finger_34_link"/>
        <child link="bh_link3_sensor5_link"/>
    </joint>
    <link name="bh_link3_sensor5_link">
        <inertial>
            <mass value="0.1"/>
            <origin rpy="0 0 0" xyz="0 0 0"/>
            <inertia ixx="0.01" ixy="0" ixz="0" iyy="0.01" iyz="0" izz="0.01"/>
        </inertial>
        <visual>
            <origin rpy="0 0 0" xyz="0 0 0"/>
            <material name="Blue"/>
            <geometry>
                <box size="0.0015 0.0055 0.0047"/>
            </geometry>
        </visual>
        <collision>
            <origin rpy="0 0 0" xyz="0 0 0"/>
            <material name="Blue"/>
            <geometry>
                <box size="0.0015 0.0055 0.0047"/>
            </geometry>
        </collision>
    </link>
    <joint name="bh_link3_sensor6_joint" type="fixed">
        <origin rpy="0 0 0" xyz="0.0105 0.02825 0.0052"/>
        <parent link="bh_finger_34_link"/>
        <child link="bh_link3_sensor6_link"/>
    </joint>
    <link name="bh_link3_sensor6_link">
        <inertial>
            <mass value="0.1"/>
            <origin rpy="0 0 0" xyz="0 0 0"/>
            <inertia ixx="0.01" ixy="0" ixz="0" iyy="0.01" iyz="0" izz="0.01"/>
        </inertial>
        <visual>
            <origin rpy="0 0 0" xyz="0 0 0"/>
            <material name="Blue"/>
            <geometry>
                <box size="0.0015 0.0055 0.0047"/>
            </geometry>
        </visual>
        <collision>
            <origin rpy="0 0 0" xyz="0 0 0"/>
            <material name="Blue"/>
            <geometry>
                <box size="0.0015 0.0055 0.0047"/>
            </geometry>
        </collision>
    </link>
    <joint name="bh_link3_sensor7_joint" type="fixed">
        <origin rpy="0 0 0" xyz="0.0105 0.03425 -0.005175"/>
        <parent link="bh_finger_34_link"/>
        <child link="bh_link3_sensor7_link"/>
    </joint>
    <link name="bh_link3_sensor7_link">
        <inertial>
            <mass value="0.1"/>
            <origin rpy="0 0 0" xyz="0 0 0"/>
            <inertia ixx="0.01" ixy="0" ixz="0" iyy="0.01" iyz="0" izz="0.01"/>
        </inertial>
        <visual>
            <origin rpy="0 0 0" xyz="0 0 0"/>
            <material name="Blue"/>
            <geometry>
                <box size="0.0015 0.0055 0.00465"/>
            </geometry>
        </visual>
        <collision>
            <origin rpy="0 0 0" xyz="0 0 0"/>
            <material name="Blue"/>
            <geometry>
                <box size="0.0015 0.0055 0.00465"/>
            </geometry>
        </collision>
    </link>
    <joint name="bh_link3_sensor8_joint" type="fixed">
        <origin rpy="0 0 0" xyz="0.0105 0.03425 0.0"/>
        <parent link="bh_finger_34_link"/>
        <child link="bh_link3_sensor8_link"/>
    </joint>
    <link name="bh_link3_sensor8_link">
        <inertial>
            <mass value="0.1"/>
            <origin rpy="0 0 0" xyz="0 0 0"/>
            <inertia ixx="0.01" ixy="0" ixz="0" iyy="0.01" iyz="0" izz="0.01"/>
        </inertial>
        <visual>
            <origin rpy="0 0 0" xyz="0 0 0"/>
            <material name="Blue"/>
            <geometry>
                <box size="0.0015 0.0055 0.0047"/>
            </geometry>
        </visual>
        <collision>
            <origin rpy="0 0 0" xyz="0 0 0"/>
            <material name="Blue"/>
            <geometry>
                <box size="0.0015 0.0055 0.0047"/>
            </geometry>
        </collision>
    </link>
    <joint name="bh_link3_sensor9_joint" type="fixed">
        <origin rpy="0 0 0" xyz="0.0105 0.03425 0.0052"/>
        <parent link="bh_finger_34_link"/>
        <child link="bh_link3_sensor9_link"/>
    </joint>
    <link name="bh_link3_sensor9_link">
        <inertial>
            <mass value="0.1"/>
            <origin rpy="0 0 0" xyz="0 0 0"/>
            <inertia ixx="0.01" ixy="0" ixz="0" iyy="0.01" iyz="0" izz="0.01"/>
        </inertial>
        <visual>
            <origin rpy="0 0 0" xyz="0 0 0"/>
            <material name="Blue"/>
            <geometry>
                <box size="0.0015 0.0055 0.0047"/>
            </geometry>
        </visual>
        <collision>
            <origin rpy="0 0 0" xyz="0 0 0"/>
            <material name="Blue"/>
            <geometry>
                <box size="0.0015 0.0055 0.0047"/>
            </geometry>
        </collision>
    </link>
    <joint name="bh_link3_sensor10_joint" type="fixed">
        <origin rpy="0 0 0" xyz="0.0105 0.04025 -0.005175"/>
        <parent link="bh_finger_34_link"/>
        <child link="bh_link3_sensor10_link"/>
    </joint>
    <link name="bh_link3_sensor10_link">
        <inertial>
            <mass value="0.1"/>
            <origin rpy="0 0 0" xyz="0 0 0"/>
            <inertia ixx="0.01" ixy="0" ixz="0" iyy="0.01" iyz="0" izz="0.01"/>
        </inertial>
        <visual>
            <origin rpy="0 0 0" xyz="0 0 0"/>
            <material name="Blue"/>
            <geometry>
                <box size="0.0015 0.0055 0.00465"/>
            </geometry>
        </visual>
        <collision>
            <origin rpy="0 0 0" xyz="0 0 0"/>
            <material name="Blue"/>
            <geometry>
                <box size="0.0015 0.0055 0.00465"/>
            </geometry>
        </collision>
    </link>
    <joint name="bh_link3_sensor11_joint" type="fixed">
        <origin rpy="0 0 0" xyz="0.0105 0.04025 0.0"/>
        <parent link="bh_finger_34_link"/>
        <child link="bh_link3_sensor11_link"/>
    </joint>
    <link name="bh_link3_sensor11_link">
        <inertial>
            <mass value="0.1"/>
            <origin rpy="0 0 0" xyz="0 0 0"/>
            <inertia ixx="0.01" ixy="0" ixz="0" iyy="0.01" iyz="0" izz="0.01"/>
        </inertial>
        <visual>
            <origin rpy="0 0 0" xyz="0 0 0"/>
            <material name="Blue"/>
            <geometry>
                <box size="0.0015 0.0055 0.0047"/>
            </geometry>
        </visual>
        <collision>
            <origin rpy="0 0 0" xyz="0 0 0"/>
            <material name="Blue"/>
            <geometry>
                <box size="0.0015 0.0055 0.0047"/>
            </geometry>
        </collision>
    </link>
    <joint name="bh_link3_sensor12_joint" type="fixed">
        <origin rpy="0 0 0" xyz="0.0105 0.04025 0.0052"/>
        <parent link="bh_finger_34_link"/>
        <child link="bh_link3_sensor12_link"/>
    </joint>
    <link name="bh_link3_sensor12_link">
        <inertial>
            <mass value="0.1"/>
            <origin rpy="0 0 0" xyz="0 0 0"/>
            <inertia ixx="0.01" ixy="0" ixz="0" iyy="0.01" iyz="0" izz="0.01"/>
        </inertial>
        <visual>
            <origin rpy="0 0 0" xyz="0 0 0"/>
            <material name="Blue"/>
            <geometry>
                <box size="0.0015 0.0055 0.0047"/>
            </geometry>
        </visual>
        <collision>
            <origin rpy="0 0 0" xyz="0 0 0"/>
            <material name="Blue"/>
            <geometry>
                <box size="0.0015 0.0055 0.0047"/>
            </geometry>
        </collision>
    </link>
    <joint name="bh_link3_sensor13_joint" type="fixed">
        <origin rpy="0 0 0" xyz="0.0095 0.04625 -0.005175"/>
        <parent link="bh_finger_34_link"/>
        <child link="bh_link3_sensor13_link"/>
    </joint>
    <link name="bh_link3_sensor13_link">
        <inertial>
            <mass value="0.1"/>
            <origin rpy="0 0 0" xyz="0 0 0"/>
            <inertia ixx="0.01" ixy="0" ixz="0" iyy="0.01" iyz="0" izz="0.01"/>
        </inertial>
        <visual>
            <origin rpy="0 0 0" xyz="0 0 0"/>
            <material name="Blue"/>
            <geometry>
                <box size="0.0015 0.0055 0.00465"/>
            </geometry>
        </visual>
        <collision>
            <origin rpy="0 0 0" xyz="0 0 0"/>
            <material name="Blue"/>
            <geometry>
                <box size="0.0015 0.0055 0.00465"/>
            </geometry>
        </collision>
    </link>
    <joint name="bh_link3_sensor14_joint" type="fixed">
        <origin rpy="0 0 0" xyz="0.0095 0.04625 0.0"/>
        <parent link="bh_finger_34_link"/>
        <child link="bh_link3_sensor14_link"/>
    </joint>
    <link name="bh_link3_sensor14_link">
        <inertial>
            <mass value="0.1"/>
            <origin rpy="0 0 0" xyz="0 0 0"/>
            <inertia ixx="0.01" ixy="0" ixz="0" iyy="0.01" iyz="0" izz="0.01"/>
        </inertial>
        <visual>
            <origin rpy="0 0 0" xyz="0 0 0"/>
            <material name="Blue"/>
            <geometry>
                <box size="0.0015 0.0055 0.0047"/>
            </geometry>
        </visual>
        <collision>
            <origin rpy="0 0 0" xyz="0 0 0"/>
            <material name="Blue"/>
            <geometry>
                <box size="0.0015 0.0055 0.0047"/>
            </geometry>
        </collision>
    </link>
    <joint name="bh_link3_sensor15_joint" type="fixed">
        <origin rpy="0 0 0" xyz="0.0095 0.04625 0.0052"/>
        <parent link="bh_finger_34_link"/>
        <child link="bh_link3_sensor15_link"/>
    </joint>
    <link name="bh_link3_sensor15_link">
        <inertial>
            <mass value="0.1"/>
            <origin rpy="0 0 0" xyz="0 0 0"/>
            <inertia ixx="0.01" ixy="0" ixz="0" iyy="0.01" iyz="0" izz="0.01"/>
        </inertial>
        <visual>
            <origin rpy="0 0 0" xyz="0 0 0"/>
            <material name="Blue"/>
            <geometry>
                <box size="0.0015 0.0055 0.0047"/>
            </geometry>
        </visual>
        <collision>
            <origin rpy="0 0 0" xyz="0 0 0"/>
            <material name="Blue"/>
            <geometry>
                <box size="0.0015 0.0055 0.0047"/>
            </geometry>
        </collision>
    </link>
    <joint name="bh_link3_sensor16_joint" type="fixed">
        <origin rpy="0 0 0" xyz="0.008 0.051 -0.005175"/>
        <parent link="bh_finger_34_link"/>
        <child link="bh_link3_sensor16_link"/>
    </joint>
    <link name="bh_link3_sensor16_link">
        <inertial>
            <mass value="0.1"/>
            <origin rpy="0 0 0" xyz="0 0 0"/>
            <inertia ixx="0.01" ixy="0" ixz="0" iyy="0.01" iyz="0" izz="0.01"/>
        </inertial>
        <visual>
            <origin rpy="0 0 0" xyz="0 0 0"/>
            <material name="Blue"/>
            <geometry>
                <box size="0.003 0.003 0.00465"/>
            </geometry>
        </visual>
        <collision>
            <origin rpy="0 0 0" xyz="0 0 0"/>
            <material name="Blue"/>
            <geometry>
                <box size="0.003 0.003 0.00465"/>
            </geometry>
        </collision>
    </link>
    <joint name="bh_link3_sensor17_joint" type="fixed">
        <origin rpy="0 0 0" xyz="0.008 0.051 0.0"/>
        <parent link="bh_finger_34_link"/>
        <child link="bh_link3_sensor17_link"/>
    </joint>
    <link name="bh_link3_sensor17_link">
        <inertial>
            <mass value="0.1"/>
            <origin rpy="0 0 0" xyz="0 0 0"/>
            <inertia ixx="0.01" ixy="0" ixz="0" iyy="0.01" iyz="0" izz="0.01"/>
        </inertial>
        <visual>
            <origin rpy="0 0 0" xyz="0 0 0"/>
            <material name="Blue"/>
            <geometry>
                <box size="0.003 0.003 0.0047"/>
            </geometry>
        </visual>
        <collision>
            <origin rpy="0 0 0" xyz="0 0 0"/>
            <material name="Blue"/>
            <geometry>
                <box size="0.003 0.003 0.0047"/>
            </geometry>
        </collision>
    </link>
    <joint name="bh_link3_sensor18_joint" type="fixed">
        <origin rpy="0 0 0" xyz="0.008 0.051 0.0052"/>
        <parent link="bh_finger_34_link"/>
        <child link="bh_link3_sensor18_link"/>
    </joint>
    <link name="bh_link3_sensor18_link">
        <inertial>
            <mass value="0.1"/>
            <origin rpy="0 0 0" xyz="0 0 0"/>
            <inertia ixx="0.01" ixy="0" ixz="0" iyy="0.01" iyz="0" izz="0.01"/>
        </inertial>
        <visual>
            <origin rpy="0 0 0" xyz="0 0 0"/>
            <material name="Blue"/>
            <geometry>
                <box size="0.003 0.003 0.0047"/>
            </geometry>
        </visual>
        <collision>
            <origin rpy="0 0 0" xyz="0 0 0"/>
            <material name="Blue"/>
            <geometry>
                <box size="0.003 0.003 0.0047"/>
            </geometry>
        </collision>
    </link>
    <joint name="bh_link3_sensor19_joint" type="fixed">
        <origin rpy="0 0 0" xyz="0.005 0.05425 -0.005175"/>
        <parent link="bh_finger_34_link"/>
        <child link="bh_link3_sensor19_link"/>
    </joint>
    <link name="bh_link3_sensor19_link">
        <inertial>
            <mass value="0.1"/>
            <origin rpy="0 0 0" xyz="0 0 0"/>
            <inertia ixx="0.01" ixy="0" ixz="0" iyy="0.01" iyz="0" izz="0.01"/>
        </inertial>
        <visual>
            <origin rpy="0 0 0" xyz="0 0 0"/>
            <material name="Blue"/>
            <geometry>
                <box size="0.0065 0.0035 0.00465"/>
            </geometry>
        </visual>
        <collision>
            <origin rpy="0 0 0" xyz="0 0 0"/>
            <material name="Blue"/>
            <geometry>
                <box size="0.0065 0.0035 0.00465"/>
            </geometry>
        </collision>
    </link>
    <joint name="bh_link3_sensor20_joint" type="fixed">
        <origin rpy="0 0 0" xyz="0.005 0.05425 0.0"/>
        <parent link="bh_finger_34_link"/>
        <child link="bh_link3_sensor20_link"/>
    </joint>
    <link name="bh_link3_sensor20_link">
        <inertial>
            <mass value="0.1"/>
            <origin rpy="0 0 0" xyz="0 0 0"/>
            <inertia ixx="0.01" ixy="0" ixz="0" iyy="0.01" iyz="0" izz="0.01"/>
        </inertial>
        <visual>
            <origin rpy="0 0 0" xyz="0 0 0"/>
            <material name="Blue"/>
            <geometry>
                <box size="0.0065 0.0035 0.0047"/>
            </geometry>
        </visual>
        <collision>
            <origin rpy="0 0 0" xyz="0 0 0"/>
            <material name="Blue"/>
            <geometry>
                <box size="0.0065 0.0035 0.0047"/>
            </geometry>
        </collision>
    </link>
    <joint name="bh_link3_sensor21_joint" type="fixed">
        <origin rpy="0 0 0" xyz="0.005 0.05425 0.0052"/>
        <parent link="bh_finger_34_link"/>
        <child link="bh_link3_sensor21_link"/>
    </joint>
    <link name="bh_link3_sensor21_link">
        <inertial>
            <mass value="0.1"/>
            <origin rpy="0 0 0" xyz="0 0 0"/>
            <inertia ixx="0.01" ixy="0" ixz="0" iyy="0.01" iyz="0" izz="0.01"/>
        </inertial>
        <visual>
            <origin rpy="0 0 0" xyz="0 0 0"/>
            <material name="Blue"/>
            <geometry>
                <box size="0.0065 0.0035 0.0047"/>
            </geometry>
        </visual>
        <collision>
            <origin rpy="0 0 0" xyz="0 0 0"/>
            <material name="Blue"/>
            <geometry>
                <box size="0.0065 0.0035 0.0047"/>
            </geometry>
        </collision>
    </link>
    <joint name="bh_link3_sensor22_joint" type="fixed">
        <origin rpy="0 0 0" xyz="0.003 0.056625 -0.005175"/>
        <parent link="bh_finger_34_link"/>
        <child link="bh_link3_sensor22_link"/>
    </joint>
    <link name="bh_link3_sensor22_link">
        <inertial>
            <mass value="0.1"/>
            <origin rpy="0 0 0" xyz="0 0 0"/>
            <inertia ixx="0.01" ixy="0" ixz="0" iyy="0.01" iyz="0" izz="0.01"/>
        </inertial>
        <visual>
            <origin rpy="0 0 0" xyz="0 0 0"/>
            <material name="Blue"/>
            <geometry>
                <box size="0.00875 0.0015 0.00465"/>
            </geometry>
        </visual>
        <collision>
            <origin rpy="0 0 0" xyz="0 0 0"/>
            <material name="Blue"/>
            <geometry>
                <box size="0.00875 0.0015 0.00465"/>
            </geometry>
        </collision>
    </link>
    <joint name="bh_link3_sensor23_joint" type="fixed">
        <origin rpy="0 0 0" xyz="0.003 0.056625 0.0"/>
        <parent link="bh_finger_34_link"/>
        <child link="bh_link3_sensor23_link"/>
    </joint>
    <link name="bh_link3_sensor23_link">
        <inertial>
            <mass value="0.1"/>
            <origin rpy="0 0 0" xyz="0 0 0"/>
            <inertia ixx="0.01" ixy="0" ixz="0" iyy="0.01" iyz="0" izz="0.01"/>
        </inertial>
        <visual>
            <origin rpy="0 0 0" xyz="0 0 0"/>
            <material name="Blue"/>
            <geometry>
                <box size="0.00875 0.0015 0.0047"/>
            </geometry>
        </visual>
        <collision>
            <origin rpy="0 0 0" xyz="0 0 0"/>
            <material name="Blue"/>
            <geometry>
                <box size="0.00875 0.0015 0.0047"/>
            </geometry>
        </collision>
    </link>
    <joint name="bh_link3_sensor24_joint" type="fixed">
        <origin rpy="0 0 0" xyz="0.003 0.056625 0.0052"/>
        <parent link="bh_finger_34_link"/>
        <child link="bh_link3_sensor24_link"/>
    </joint>
    <link name="bh_link3_sensor24_link">
        <inertial>
            <mass value="0.1"/>
            <origin rpy="0 0 0" xyz="0 0 0"/>
            <inertia ixx="0.01" ixy="0" ixz="0" iyy="0.01" iyz="0" izz="0.01"/>
        </inertial>
        <visual>
            <origin rpy="0 0 0" xyz="0 0 0"/>
            <material name="Blue"/>
            <geometry>
                <box size="0.00875 0.0015 0.0047"/>
            </geometry>
        </visual>
        <collision>
            <origin rpy="0 0 0" xyz="0 0 0"/>
            <material name="Blue"/>
            <geometry>
                <box size="0.00875 0.0015 0.0047"/>
            </geometry>
        </collision>
    </link>
</robot>

